Workbook

Sheet Ind_est_fís_Brasil
A1: Indicadores de Estoques e Físicos: Brasil, 2018-2020
A3: Indicadores | B3: Unidade | C3: 2018 | D3: 2019 | E3: 2020
A5: INDICADORES DE ESTOQUE
A6: Total de Recursos Hídricos Renováveis (TRHR) | B6: hm3 | C6: 8306766 | D6: 8380734 | E6: 6733794
A7: Total de Recursos Hídricos Renováveis (TRHR) per capita | B7: m3/habitante/ano | C7: 39841.579 | D7: 39880.317 | E7: 31799.825
A8: Índice de Retirada (IR) - Volume captado como proporção do TRHR | B8: % | C8: 6.7891631 | D8: 6.7244128 | E8: 8.5436591
A9: Razão de dependência (RD) - Volume de entradas de outros países a montante como proporção de TRHR | B9: % | C9: 34.327703 | D9: 35.186071 | E9: 36.086937
A11: INDICADORES FÍSICOS
A12: Retirada total de água
A13: Participação das atividades econômicas na retirada total | B13: % | C13: 99.982518 | D13: 99.983184 | E13: 99.983286
A14: Agricultura, pecuária, produção florestal, pesca e aquicultura | B14: % | C14: 13.310568 | D14: 12.885471 | E14: 13.181538
A15: Indústrias extrativas | B15: % | C15: 0.021049649 | D15: 0.021334468 | E15: 0.022313729
A16: Indústrias de transformação e construção | B16: % | C16: 0.14461974 | D16: 0.14090868 | E16: 0.1449211
A17: Eletricidade e gás | B17: % | C17: 85.058002 | D17: 85.528523 | E17: 85.247188
A18: Água e esgoto | B18: % | C18: 1.4482788 | D18: 1.4069466 | E18: 1.3873252
A19: Demais atividades | B19: % | C19: 0 | D19: 0 | E19: 0
A20: Participação das Famílias na retirada total | B20: % | C20: 0.017481885 | D20: 0.016815892 | E20: 0.016713603
A22: Uso total da água
A23: Participação das atividades econômicas no uso total da água | B23: % | C23: 99.781862 | D23: 99.784372 | E23: 99.781522
A24: Agricultura, pecuária, produção florestal, pesca e aquicultura | B24: % | C24: 13.288996 | D24: 12.868084 | E24: 13.157456
A25: Indústrias extrativas | B25: % | C25: 0.021164753 | D25: 0.021445295 | E25: 0.022426845
A26: Indústrias de transformação e construção | B26: % | C26: 0.1498163 | D26: 0.14595843 | E26: 0.14963678
A27: Eletricidade e gás | B27: % | C27: 84.671418 | D27: 85.136986 | E27: 84.863735
A28: Água e esgoto | B28: % | C28: 1.6030552 | D28: 1.564611 | E28: 1.5447308
A29: Demais atividades | B29: % | C29: 0.04741189 | D29: 0.047287079 | E29: 0.04353742
A30: Participação das Famílias no uso total da água | B30: % | C30: 0.21813764 | D30: 0.21562798 | E30: 0.21847798
A32: Retorno total para o meio ambiente
A33: Participação das atividades econômicas no retorno total | B33: % | C33: 99.95485 | D33: 99.958152 | E33: 99.957214
A34: Agricultura, pecuária, produção florestal, pesca e aquicultura | B34: % | C34: 6.692728 | D34: 6.360664 | E34: 6.5215528
A35: Indústrias extrativas | B35: % | C35: 0.016012917 | D35: 0.016199 | E35: 0.017009187
A36: Indústrias de transformação e construção | B36: % | C36: 0.075010859 | D36: 0.072427639 | E36: 0.075174575
A37: Eletricidade e gás | B37: % | C37: 91.812407 | D37: 92.195593 | E37: 92.051593
A38: Água e esgoto | B38: % | C38: 1.3502007 | D38: 1.3054928 | E38: 1.2854673
A39: Demais atividades | B39: % | C39: 0.0084906486 | D39: 0.0077754112 | E39: 0.0064173079
A40: Participação das Famílias no retorno total | B40: % | C40: 0.045149664 | D40: 0.041848008 | E40: 0.042786165
A42: Consumo total
A43: Participação das atividades econômicas no consumo total | B43: % | C43: 99.310639 | D43: 99.307419 | E43: 99.313509
A44: Agricultura, pecuária, produção florestal, pesca e aquicultura | B44: % | C44: 97.158136 | D44: 97.143225 | E44: 97.062521
A45: Indústrias extrativas | B45: % | C45: 0.085433718 | D45: 0.088044614 | E45: 0.089489247
A46: Indústrias de transformação e construção | B46: % | C46: 1.0483757 | D46: 1.0431495 | E46: 1.0383672
...

Sheet Ind_est_fís_Grandes Regiões
A1: Indicadores de Estoques e Físicos: grandes regiões, 2020
A3: Indicadores | B3: Unidade | C3: N | D3: NE | E3: SE | F3: S | G3: CO
A5: INDICADORES DE ESTOQUE
A6: Total de Recursos Hídricos Renováveis (TRHR) | B6: hm3 | C6: 6195556 | D6: 337681 | E6: 314625 | F6: 350670 | G6: 495157
A7: Total de Recursos Hídricos Renováveis (TRHR) per capita | B7: m3/habitante/ano | C7: 331799.48 | D7: 5885.5853 | E7: 3534.6262 | F7: 11614.545 | G7: 30001.691
A8: Índice de Retirada (IR) - Volume captado como proporção do TRHR | B8: % | C8: 0.8196012 | D8: 20.855949 | E8: 47.316398 | F8: 38.626586 | G8: 34.289309
A9: Razão de dependência (RD) - Volume de entradas de outros países e/ou regiões a montante como proporção de TRHR | B9: % | C9: 47.669313 | D9: 38.42443 | E9: 17.14994 | F9: 36.051273 | G9: 25.528267
A11: INDICADORES FÍSICOS
A12: Retirada total de água
A13: Participação das atividades econômicas na retirada total | B13: % | C13: 99.976961 | D13: 99.913652 | E13: 99.991954 | F13: 99.981358 | G13: 99.99431
A14: Agricultura, pecuária, produção florestal, pesca e aquicultura | B14: % | C14: 8.7316207 | D14: 20.648493 | E14: 6.6364322 | F14: 26.998005 | G14: 22.176972
A15: Indústrias extrativas | B15: % | C15: 0.051027392 | D15: 0.0062820537 | E15: 0.026356173 | F15: 0.010570873 | G15: 0.004417883
A16: Indústrias de transformação e construção | B16: % | C16: 0.027594738 | D16: 0.40461953 | E16: 0.13376283 | F16: 0.22287111 | G16: 0.10493236
A17: Eletricidade e gás | B17: % | C17: 90.360345 | D17: 75.288739 | E17: 91.92519 | F17: 70.739206 | G17: 76.869245
A18: Água e esgoto | B18: % | C18: 0.80637314 | D18: 3.5655186 | E18: 1.2702126 | F18: 2.0107047 | G18: 0.83874157
A19: Demais atividades | B19: % | C19: 0 | D19: 0 | E19: 0 | F19: 0 | G19: 0
A20: Participação das Famílias na retirada total | B20: % | C20: 0.023038849 | D20: 0.086348327 | E20: 0.0080463175 | F20: 0.018642137 | G20: 0.005690271
A22: Uso total da água
A23: Participação das atividades econômicas no uso total da água | B23: % | C23: 99.903414 | D23: 99.428948 | E23: 99.770851 | F23: 99.72351 | G23: 99.904011
A24: Agricultura, pecuária, produção florestal, pesca e aquicultura | B24: % | C24: 8.7350964 | D24: 20.731635 | E24: 6.6084659 | F24: 26.889726 | G24: 22.138036
A25: Indústrias extrativas | B25: % | C25: 0.051126557 | D25: 0.0065991907 | E25: 0.02654414 | F25: 0.010545843 | G25: 0.0044176216
A26: Indústrias de transformação e construção | B26: % | C26: 0.029224234 | D26: 0.40811447 | E26: 0.13949092 | F26: 0.23087547 | G26: 0.10629896
A27: Eletricidade e gás | B27: % | C27: 90.230424 | D27: 74.361319 | E27: 91.480642 | F27: 70.334882 | G27: 76.729798
A28: Água e esgoto | B28: % | C28: 0.82681688 | D28: 3.8141192 | E28: 1.4713108 | F28: 2.2050569 | G28: 0.90687186
A29: Demais atividades | B29: % | C29: 0.030726164 | D29: 0.10716147 | E29: 0.044397041 | F29: 0.052424005 | G29: 0.018589208
A30: Participação das Famílias no uso total da água | B30: % | C30: 0.09658618 | D30: 0.57105204 | E30: 0.22914893 | F30: 0.2764898 | G30: 0.095988735
A32: Retorno total para o meio ambiente
A33: Participação das atividades econômicas no retorno total | B33: % | C33: 99.929997 | D33: 99.742714 | E33: 99.990059 | F33: 99.942851 | G33: 99.97848
A34: Agricultura, pecuária, produção florestal, pesca e aquicultura | B34: % | C34: 5.6499601 | D34: 10.071665 | E34: 2.6102994 | F34: 14.077085 | G34: 12.528415
A35: Indústrias extrativas | B35: % | C35: 0.03627583 | D35: 0.0036530423 | E35: 0.020017018 | F35: 0.0092063034 | G35: 0.0030138529
A36: Indústrias de transformação e construção | B36: % | C36: 0.020748245 | D36: 0.16159098 | E36: 0.062771077 | F36: 0.183841 | G36: 0.05364181
A37: Eletricidade e gás | B37: % | C37: 93.515793 | D37: 86.444529 | E37: 96.110229 | F37: 83.584553 | G37: 86.525257
A38: Água e esgoto | B38: % | C38: 0.69720792 | D38: 3.0364197 | E38: 1.183215 | F38: 2.0783307 | G38: 0.86570586
A39: Demais atividades | B39: % | C39: 0.010012025 | D39: 0.024856394 | E39: 0.0035272933 | F39: 0.0098352574 | G39: 0.0024471142
A40: Participação das Famílias no retorno total | B40: % | C40: 0.070002676 | D40: 0.25728638 | E40: 0.0099411716 | F40: 0.057148621 | G40: 0.021519799
A42: Consumo total
A43: Participação das atividades econômicas no consumo total | B43: % | C43: =[1]Indicadores_fís_site_regiões!C43*100 -> 99.593062 | D43: =[1]Indicadores_fís_site_regiões!D43*100 -> 99.031283 | E43: =[1]Indicadores_fís_site_regiões!E43*100 -> 98.704813 | F43: =[1]Indicadores_fís_site_regiões!F43*100 -> 99.570535 | G43: =[1]Indicadores_fís_site_regiões!G43*100 -> 99.798318
A44: Agricultura, pecuária, produção florestal, pesca e aquicultura | B44: % | C44: =[1]Indicadores_fís_site_regiões!C44*100 -> 97.391132 | D44: =[1]Indicadores_fís_site_regiões!D44*100 -> 94.583221 | E44: =[1]Indicadores_fís_site_regiões!E44*100 -> 95.14001 | F44: =[1]Indicadores_fís_site_regiões!F44*100 -> 98.410348 | G44: =[1]Indicadores_fís_site_regiões!G44*100 -> 98.995964
A45: Indústrias extrativas | B45: % | C45: =[1]Indicadores_fís_site_regiões!C45*100 -> 0.47747358 | D45: =[1]Indicadores_fís_site_regiões!D45*100 -> 0.025163695 | E45: =[1]Indicadores_fís_site_regiões!E45*100 -> 0.16661937 | F45: =[1]Indicadores_fís_site_regiões!F45*100 -> 0.018152396 | G45: =[1]Indicadores_fís_site_regiões!G45*100 -> 0.015614469
A46: Indústrias de transformação e construção | B46: % | C46: =[1]Indicadores_fís_site_regiões!C46*100 -> 0.26462208 | D46: =[1]Indicadores_fís_site_regiões!D46*100 -> 2.0721872 | E46: =[1]Indicadores_fís_site_regiões!E46*100 -> 1.7193715 | F46: =[1]Indicadores_fís_site_regiões!F46*100 -> 0.45778317 | G46: =[1]Indicadores_fís_site_regiões!G46*100 -> 0.51691365
...
