Workbook
Name _Lisez_moi: OFFSET([0]!po,#REF!,0)
Name ad: OFFSET(po,#REF!,0)
Name AxeF1: OFFSET('[1]Figure 1'!$A$2,0,0,COUNTIF('[1]Figure 1'!$A$2:$A$250,"<>NA"),1)
Name AxeF4: OFFSET('[1]Figure 4'!$A$2,0,0,COUNTIF('[1]Figure 4'!$A$2:$A$307,"<>NA"),1)
Name AxeF5: OFFSET('[1]Figure 5'!$A$2,0,0,COUNTIF('[1]Figure 5'!$A$2:$A$250,"<>NA"),1)
Name bilan_circ: #REF!
Name bilan_dep: #REF!
Name bilan_dep_a17_secret: #REF!
Name bilan_dep_taille_ent: #REF!
Name bilan_dep_taille_ent_NM: #REF!
Name bilan_dep_taille_etab: #REF!
Name bilan_dep_taille_etab_NM: #REF!
Name bilan_depot: #REF!
Name bilan_motif: #REF!
Name bilan_naf17: #REF!
Name bilan_naf38: #REF!
Name bilan_naf88: #REF!
Name bilan_reg: #REF!
Name bilan_REV2: #REF!
Name bilan_statut: #REF!
Name bilan_taille_ent: #REF!
Name bilan_taille_ent_b: #REF!
Name bilan_taille_etab: #REF!
Name bilan_taille_etab_b: #REF!
Name blabla: #REF!
Name brute: #REF!
Name choix: OFFSET(periode,#REF!,0)
Name choix_mesure: OFFSET(periode,#REF!,0)
Name choix_mesure2: OFFSET(periode,#REF!,0)
Name Cout_mh_avril_0J: INDEX([1]Data!$A$4:$SG$3992,MATCH(DATE(YEAR(date_ref),MONTH(date_ref),DAY(date_ref)- "0"),[1]Data!$A$4:$A$3992,0),MATCH("Cout_mh_avril",[1]Data!$A$3:$SG$3,0))
Name Cout_mh_mai_0J: INDEX([1]Data!$A$4:$SG$4000,MATCH(DATE(YEAR(date_ref),MONTH(date_ref),DAY(date_ref)- "0"),[1]Data!$A$4:$A$4000,0),MATCH("Cout_mh_mai",[1]Data!$A$3:$SG$3,0))
Name Cout_mh_mars_0J: INDEX([1]Data!$A$4:$SG$3992,MATCH(DATE(YEAR(date_ref),MONTH(date_ref),DAY(date_ref)- "0"),[1]Data!$A$4:$A$3992,0),MATCH("Cout_mh_mars",[1]Data!$A$3:$SG$3,0))
Name CVS_DUR: [2]données_graph1!#REF!
Name cvscjo: #REF!
Name DAP_avril_0J: INDEX([1]Data!$A$4:$SG$3992,MATCH(DATE(YEAR(date_ref),MONTH(date_ref),DAY(date_ref)- "0"),[1]Data!$A$4:$A$3992,0),MATCH("DAP_avril",[1]Data!$A$3:$SG$3,0))
Name DAP_mai_0J: INDEX([1]Data!$A$4:$SG$4000,MATCH(DATE(YEAR(date_ref),MONTH(date_ref),DAY(date_ref)- "0"),[1]Data!$A$4:$A$4000,0),MATCH("DAP_mai",[1]Data!$A$3:$SG$3,0))
Name DAP_mars_0J: INDEX([1]Data!$A$4:$SG$3992,MATCH(DATE(YEAR(date_ref),MONTH(date_ref),DAY(date_ref)- "0"),[1]Data!$A$4:$A$3992,0),MATCH("DAP_mars",[1]Data!$A$3:$SG$3,0))
Name date_ref: OFFSET([1]Listes!$A$6,[1]Calculs!$B$2,0)
Name defmABCDE_0T: INDEX([1]Data!$A$4:$SG$3978,MATCH(DATE(YEAR(date_ref),MONTH(date_ref)- "0",DAY(date_ref)),[1]Data!$A$4:$A$3978,0),MATCH("defmABCDE",[1]Data!$A$3:$SG$3,0))
Name DI_avril_0J: INDEX([1]Data!$A$4:$SG$3992,MATCH(DATE(YEAR(date_ref),MONTH(date_ref),DAY(date_ref)- "0"),[1]Data!$A$4:$A$3992,0),MATCH("DI_avril",[1]Data!$A$3:$SG$3,0))
Name DI_avril_val_0J: INDEX([1]Data!$A$4:$SG$3992,MATCH(DATE(YEAR(date_ref),MONTH(date_ref),DAY(date_ref)- "0"),[1]Data!$A$4:$A$3992,0),MATCH("DI_avril_val",[1]Data!$A$3:$SG$3,0))
Name DI_mai_0J: INDEX([1]Data!$A$4:$SG$4000,MATCH(DATE(YEAR(date_ref),MONTH(date_ref),DAY(date_ref)- "0"),[1]Data!$A$4:$A$4000,0),MATCH("DI_mai",[1]Data!$A$3:$SG$3,0))
Name DI_mai_val_0J: INDEX([1]Data!$A$4:$SG$4000,MATCH(DATE(YEAR(date_ref),MONTH(date_ref),DAY(date_ref)- "0"),[1]Data!$A$4:$A$4000,0),MATCH("DI_mai_val",[1]Data!$A$3:$SG$3,0))
Name DI_mars_0J: INDEX([1]Data!$A$4:$SG$3992,MATCH(DATE(YEAR(date_ref),MONTH(date_ref),DAY(date_ref)- "0"),[1]Data!$A$4:$A$3992,0),MATCH("DI_mars",[1]Data!$A$3:$SG$3,0))
Name DI_mars_val_0J: INDEX([1]Data!$A$4:$SG$3992,MATCH(DATE(YEAR(date_ref),MONTH(date_ref),DAY(date_ref)- "0"),[1]Data!$A$4:$A$3992,0),MATCH("DI_mars_val",[1]Data!$A$3:$SG$3,0))
Name DI_ul_avril_0J: INDEX([1]Data!$A$4:$SG$3992,MATCH(DATE(YEAR(date_ref),MONTH(date_ref),DAY(date_ref)- "0"),[1]Data!$A$4:$A$3992,0),MATCH("DI_ul_avril",[1]Data!$A$3:$SG$3,0))
Name DI_ul_mai_0J: INDEX([1]Data!$A$4:$SG$4000,MATCH(DATE(YEAR(date_ref),MONTH(date_ref),DAY(date_ref)- "0"),[1]Data!$A$4:$A$4000,0),MATCH("DI_ul_mai",[1]Data!$A$3:$SG$3,0))
Name DI_ul_mars_0J: INDEX([1]Data!$A$4:$SG$3992,MATCH(DATE(YEAR(date_ref),MONTH(date_ref),DAY(date_ref)- "0"),[1]Data!$A$4:$A$3992,0),MATCH("DI_ul_mars",[1]Data!$A$3:$SG$3,0))
Name Eff_DAP_att_0J: INDEX([1]Data!$A$4:$SG$3991,MATCH(DATE(YEAR(date_ref),MONTH(date_ref),DAY(date_ref)- "0"),[1]Data!$A$4:$A$3991,0),MATCH("Eff_DAP_att",[1]Data!$A$3:$SG$3,0))
Name Eff_DAP_avril_0J: INDEX([1]Data!$A$4:$SG$3992,MATCH(DATE(YEAR(date_ref),MONTH(date_ref),DAY(date_ref)- "0"),[1]Data!$A$4:$A$3992,0),MATCH("Eff_DAP_avril",[1]Data!$A$3:$SG$3,0))
Name Eff_DAP_cumul_0J: INDEX([1]Data!$A$4:$SG$3991,MATCH(DATE(YEAR(date_ref),MONTH(date_ref),DAY(date_ref)- "0"),[1]Data!$A$4:$A$3991,0),MATCH("Eff_DAP_cumul",[1]Data!$A$3:$SG$3,0))
Name Eff_DAP_mai_0J: INDEX([1]Data!$A$4:$SG$4000,MATCH(DATE(YEAR(date_ref),MONTH(date_ref),DAY(date_ref)- "0"),[1]Data!$A$4:$A$4000,0),MATCH("Eff_DAP_mai",[1]Data!$A$3:$SG$3,0))
Name Eff_DAP_mars_0J: INDEX([1]Data!$A$4:$SG$3992,MATCH(DATE(YEAR(date_ref),MONTH(date_ref),DAY(date_ref)- "0"),[1]Data!$A$4:$A$3992,0),MATCH("Eff_DAP_mars",[1]Data!$A$3:$SG$3,0))
Name Eff_DAP_poss_0J: INDEX([1]Data!$A$4:$SG$3991,MATCH(DATE(YEAR(date_ref),MONTH(date_ref),DAY(date_ref)- "0"),[1]Data!$A$4:$A$3991,0),MATCH("Eff_DAP_poss",[1]Data!$A$3:$SG$3,0))
Name Eff_DAP_r11_0J: INDEX([1]Data!$A$4:$SG$3991,MATCH(DATE(YEAR(date_ref),MONTH(date_ref),DAY(date_ref)- "0"),[1]Data!$A$4:$A$3991,0),MATCH("Eff_DAP_r11",[1]Data!$A$3:$SG$3,0))
Name Eff_DAP_r84_0J: INDEX([1]Data!$A$4:$SG$3991,MATCH(DATE(YEAR(date_ref),MONTH(date_ref),DAY(date_ref)- "0"),[1]Data!$A$4:$A$3991,0),MATCH("Eff_DAP_r84",[1]Data!$A$3:$SG$3,0))
Name Eff_DAP_refu_0J: INDEX([1]Data!$A$4:$SG$3991,MATCH(DATE(YEAR(date_ref),MONTH(date_ref),DAY(date_ref)- "0"),[1]Data!$A$4:$A$3991,0),MATCH("Eff_DAP_refu",[1]Data!$A$3:$SG$3,0))
Name Eff_DI_avril_0J: INDEX([1]Data!$A$4:$SG$3992,MATCH(DATE(YEAR(date_ref),MONTH(date_ref),DAY(date_ref)- "0"),[1]Data!$A$4:$A$3992,0),MATCH("Eff_DI_avril",[1]Data!$A$3:$SG$3,0))
Name Eff_DI_mai_0J: INDEX([1]Data!$A$4:$SG$4000,MATCH(DATE(YEAR(date_ref),MONTH(date_ref),DAY(date_ref)- "0"),[1]Data!$A$4:$A$4000,0),MATCH("Eff_DI_mai",[1]Data!$A$3:$SG$3,0))
Name Eff_DI_mars_0J: INDEX([1]Data!$A$4:$SG$3991,MATCH(DATE(YEAR(date_ref),MONTH(date_ref),DAY(date_ref)- "0"),[1]Data!$A$4:$A$3991,0),MATCH("Eff_DI_mars",[1]Data!$A$3:$SG$3,0))

Sheet Tableau 1
A1: Tableau 1 : emploi dans les activités de l'économie verte en 2021
B3: Emploi en 2021 (en ETP) | C3: Évolution 2021/2020 (en %) | F3: Emploi en 2021 (en ETP) | G3: Évolution 2021/2020 (en %)
A5: Éco-activités | B5: =ROUND(F5/100,0)*100 -> 745600 | C5: =G5 -> 11.816217 | F5: =Données!O4 -> 745641.11 | G5: =Données!P4 -> 11.816217
A6: Protection de l'environnement, dont | B6: =ROUND(F6/100,0)*100 -> 366300 | C6: =G6 -> 6.642822 | F6: =Données!O5 -> 366317.88 | G6: =Données!P5 -> 6.642822
A7: Protection de l'air et du climat | B7: =ROUND(F7/100,0)*100 -> 0 | C7: =G7 -> 0 | F7: =ROUND(J7/100,0)*100 -> 0 | G7: =ROUND(K7/100,0)*100 -> 0
A8: Gestion des eaux usées | B8: =ROUND(F8/100,0)*100 -> 57700 | C8: =G8 -> 7.949381 | F8: =Données!O7 -> 57740.51 | G8: =Données!P7 -> 7.949381
A9: Gestion des déchets | B9: =ROUND(F9/100,0)*100 -> 102000 | C9: =G9 -> 1.7152133 | F9: =Données!O8 -> 101972.57 | G9: =Données!P8 -> 1.7152133
A10: Protection contre les radiations | B10: =ROUND(F10/100,0)*100 -> 3500 | C10: =G10 -> 8.1412432 | F10: =Données!O9 -> 3541.2217 | G10: =Données!P9 -> 8.1412432
A11: Protection des sols et des masses d'eau | B11: =ROUND(F11/100,0)*100 -> 151800 | C11: =G11 -> 8.778267 | F11: =Données!O10 -> 151838.79 | G11: =Données!P10 -> 8.778267
A12: Lutte contre le bruit | B12: =ROUND(F12/100,0)*100 -> 5400 | C12: =G12 -> 23.892902 | F12: =Données!O11 -> 5438.0457 | G12: =Données!P11 -> 23.892902
A13: Protection de la biodiversité et des paysages | B13: =ROUND(F13/100,0)*100 -> 33300 | C13: =G13 -> 7.4693032 | F13: =Données!O12 -> 33323.156 | G13: =Données!P12 -> 7.4693032
A14: Gestion des ressources, dont | B14: =ROUND(F14/100,0)*100 -> 285900 | C14: =G14 -> 18.197329 | F14: =Données!O13 -> 285897.72 | G14: =Données!P13 -> 18.197329
A15: Gestion des ressources en eau | B15: =ROUND(F15/100,0)*100 -> 0 | C15: =G15 -> 0 | F15: =ROUND(J15/100,0)*100 -> 0 | G15: =ROUND(K15/100,0)*100 -> 0
A16: Gestion durable de la forêt | B16: =ROUND(F16/100,0)*100 -> 0 | C16: =G16 -> 0
A17: Récupération de matériaux de recyclage | B17: =ROUND(F17/100,0)*100 -> 34200 | C17: =G17 -> 19.906485 | F17: =Données!O16 -> 34216.393 | G17: =Données!P16 -> 19.906485
A18: Maîtrise de l'énergie | B18: =ROUND(F18/100,0)*100 -> 126900 | C18: =G18 -> 22.193438 | F18: =Données!O18 -> 126907.76 | G18: =Données!P18 -> 22.193438
A19: Production d'énergies renouvelables | B19: =ROUND(F19/100,0)*100 -> 109800 | C19: =G19 -> 15.628786 | F19: =Données!O17 -> 109781.22 | G19: =Données!P17 -> 15.628786
A20: Activités transversales, dont | B20: =ROUND(F20/100,0)*100 -> 93400 | C20: =G20 -> 14.683577 | F20: =Données!O19 -> 93425.512 | G20: =Données!P19 -> 14.683577
A21: Administration générale relative à l'environnement | B21: =ROUND(F21/100,0)*100 -> 52700 | C21: =G21 -> 15.112331 | F21: =Données!O22 -> 52724.472 | G21: =Données!P22 -> 15.112331
A22: R & D environnementale | B22: =ROUND(F22/100,0)*100 -> 27000 | C22: =G22 -> 15.970882 | F22: =Données!O21 -> 27048.439 | G22: =Données!P21 -> 15.970882
A23: Ingénierie environnementale | B23: =ROUND(F23/100,0)*100 -> 13700 | C23: =G23 -> 10.658289 | F23: =Données!O20 -> 13652.601 | G23: =Données!P20 -> 10.658289
A24: Activités périphériques, dont | B24: =ROUND(F24/100,0)*100 -> 422100 | C24: =G24 -> 6.164493 | F24: =Données!O23 -> 422118.53 | G24: =Données!P23 -> 6.164493
A25: Gestion des espaces verts | B25: =ROUND(F25/100,0)*100 -> 0 | C25: =G25 -> 0 | F25: =ROUND(J25/100,0)*100 -> 0 | G25: =ROUND(K25/100,0)*100 -> 0
A26: Transports plus durables (transports en communs, cycles) | B26: =ROUND(F26/100,0)*100 -> 380300 | C26: =G26 -> 5.0186143 | F26: =Données!O25+Données!O26 -> 380310.77 | G26: =((Données!O25+Données!O26)/(Données!N25+Données!N26)-1)*100 -> 5.0186143
A27: Transports urbains et suburbains | B27: =ROUND(F27/100,0)*100 -> 0 | C27: =G27 -> 0 | F27: =ROUND(J27/100,0)*100 -> 0 | G27: =ROUND(K27/100,0)*100 -> 0
A28: Activités de l'économie verte | B28: =ROUND(F28/100,0)*100 -> 1167800 | C28: =G28 -> 9.7051136 | F28: =Données!O27 -> 1167759.6 | G28: =Données!P27 -> 9.7051136
A29: Ensemble de l'économie | B29: =ROUND(F29/100,0)*100 -> 27611600 | C29: =G29 -> 2.915842 | F29: 27611600 | G29: 2.915842
A30: Note : les données 2021 sont provisoires ; chiffres arrondis à la centaine
A31: Champ : France.
A32: Sources : SDES, Insee, EAP, Esane, Comptes nationaux base 2014 ; Ademe ; Agence BIO. Traitements : SDES, 2023

Sheet graphique 1
A1: Graphique 1 : emploi dans les éco-activités en 2004, 2012 et 2021
A2: En équivalents temps plein
A26: Notes : données 2021 provisoires ; protection des sols et des masses d'eau : y compris agriculture biologique.
A27: Champ : France.
A28: Sources : SDES, Insee, enquête annuelle de production (EAP), Élaboration des statistiques annuelles d'entreprises (Ésane), Comptes nationaux base 2014 ; ADEME ; Agence BIO ; Traitements : SDES, 2023

Sheet graphique 2
A1: Graphique 2 : évolution de l'emploi dans les activités de l'économie verte entre 2004 et 2021 (en équivalents temps plein)
A2: Indice base 100 en 2008
A21: Notes : données 2021 provisoires ; la période d'observation des activités périphériques débute en 2008, celle des éco-activités en 2004.
A22: Champ : France.
A23: Sources : SDES, Insee, EAP, Esane, Comptes nationaux base 2014 ; Ademe ; Agence BIO. Traitements : SDES, 2023
A26: Evolution de l'emploi dans les activités de l'économie verte
A28: En équivalent temps plein
B29: 2004 | C29: 2005 | D29: 2006 | E29: 2007 | F29: 2008 | G29: 2009 | H29: 2010 | I29: 2011 | J29: 2012 | K29: 2013 | L29: 2014 | M29: 2015 | N29: 2016 | O29: 2017 | P29: 2018 | Q29: 2019 | R29: 2020 | S29: 2021p
A30: Éco-activités | B30: =Données!B48 -> 400850.65 | C30: =Données!C48 -> 420487.02 | D30: =Données!D48 -> 436145.96 | E30: =Données!E48 -> 458631.04 | F30: =Données!F48 -> 483280.91 | G30: =Données!G48 -> 515192.74 | H30: =Données!H48 -> 567175.47 | I30: =Données!I48 -> 569919.47 | ... S30: =Données!S48 -> 745641.11 | U30: =S30/F30 -> 1.5428731
A31: Activités périphériques | F31: =Données!B23 -> 373205.25 | G31: =Données!C23 -> 380839.32 | H31: =Données!D23 -> 378359.64 | I31: =Données!E23 -> 383874.75 | J31: =Données!F23 -> 392380.15 | K31: =Données!G23 -> 406085.78 | L31: =Données!H23 -> 407213.49 | M31: =Données!I23 -> 405081.26 | ... S31: =Données!O23 -> 422118.53 | U31: =S31/F31 -> 1.1310627 | V31: =S31/R31 -> 1.0616449
A32: Emploi total national | B32: 24752926 | C32: 24926025 | D32: 25286523 | E32: 25669677 | F32: 25778077 | G32: 25496092 | H32: 25492018 | I32: 25617729 | J32: 25646549 | K32: 25681750 | L32: 25769574 | M32: 25856022 | N32: 25972690 | O32: 26259873 | P32: 26518426 | Q32: 26859111 | R32: 26829300 | S32: 27611600
A35: En indice base 100 en 2008
B36: 2004 | C36: 2005 | D36: 2006 | E36: 2007 | F36: 2008 | G36: 2009 | H36: 2010 | I36: 2011 | J36: 2012 | K36: 2013 | L36: 2014 | M36: 2015 | N36: 2016 | O36: 2017 | P36: 2018 | Q36: 2019 | R36: 2020 | S36: 2021
A37: Éco-activités | B37: =B30/$F30*100 -> 82.943614 | C37: =C30/$F30*100 -> 87.006753 | D37: =D30/$F30*100 -> 90.246884 | E37: =E30/$F30*100 -> 94.899474 | F37: =F30/$F30*100 -> 100 | G37: =G30/$F30*100 -> 106.60316 | H37: =H30/$F30*100 -> 117.35938 | I37: =I30/$F30*100 -> 117.92717 | ... S37: =S30/$F30*100 -> 154.28731
A38: Activités périphériques | F38: =F31/$F31*100 -> 100 | G38: =G31/$F31*100 -> 102.04554 | H38: =H31/$F31*100 -> 101.38111 | I38: =I31/$F31*100 -> 102.85888 | J38: =J31/$F31*100 -> 105.1379 | K38: =K31/$F31*100 -> 108.81031 | L38: =L31/$F31*100 -> 109.11248 | M38: =M31/$F31*100 -> 108.54115 | ... S38: =S31/$F31*100 -> 113.10627
A39: Emploi total national | B39: =B32/$F32*100 -> 96.023168 | C39: =C32/$F32*100 -> 96.694663 | D39: =D32/$F32*100 -> 98.093132 | E39: =E32/$F32*100 -> 99.579489 | F39: =F32/$F32*100 -> 100 | G39: =G32/$F32*100 -> 98.906104 | H39: =H32/$F32*100 -> 98.890299 | I39: =I32/$F32*100 -> 99.377967 | ... S39: =S32/$F32*100 -> 107.11272

Sheet Données
A1: Emploi dans les activités de l'économie verte entre 2008 et 2021
A3: Domaine environnemental | B3: 2008 | C3: 2009 | D3: 2010 | E3: 2011 | F3: 2012 | G3: 2013 | H3: 2014 | I3: 2015 | J3: 2016 | K3: 2017 | L3: 2018 | M3: 2019 | N3: 2020 | O3: 2021p | P3: Evol. n/n-1
A4: Eco-activités | B4: =B5+B13+B19 -> 483280.91 | C4: =C5+C13+C19 -> 515192.74 | D4: =D5+D13+D19 -> 567175.47 | E4: =E5+E13+E19 -> 569919.47 | F4: =F5+F13+F19 -> 565869.47 | G4: =G5+G13+G19 -> 569773.84 | H4: =H5+H13+H19 -> 569289.33 | I4: =I5+I13+I19 -> 577332.25 | ... O4: =O5+O13+O19 -> 745641.11 | P4: =(O4/N4-1)*100 -> 11.816217
A5: Protection de l'environnement | B5: =SUM(B6:B12) -> 225530.77 | C5: =SUM(C6:C12) -> 237707.1 | D5: =SUM(D6:D12) -> 249465.63 | E5: =SUM(E6:E12) -> 255730.38 | F5: =SUM(F6:F12) -> 264786.2 | G5: =SUM(G6:G12) -> 268264.86 | H5: =SUM(H6:H12) -> 273148.99 | I5: =SUM(I6:I12) -> 278378.31 | ... O5: =SUM(O6:O12) -> 366317.88 | P5: =(O5/N5-1)*100 -> 6.642822
A6: Air | B6: 8372.3343 | C6: 7187.6466 | D6: 6842.6751 | E6: 6361.6686 | F6: 6790.7796 | G6: 7204.3887 | H6: 7369.3422 | I6: 7993.5402 | J6: 7848.4927 | K6: 8236.7474 | L6: 9049.2129 | M6: 9342.1265 | N6: 11501.61 | O6: 12463.59 | P6: =(O6/N6-1)*100 -> 8.3638672
A7: Eaux_usées | B7: 59768.01 | C7: 60562.006 | D7: 60121.44 | E7: 58061.193 | F7: 55643.181 | G7: 57256.337 | H7: 57462.402 | I7: 55284.521 | J7: 53487.949 | K7: 54444.276 | L7: 54146.919 | M7: 54721.273 | N7: 53488.505 | O7: 57740.51 | P7: =(O7/N7-1)*100 -> 7.949381
A8: Déchets | B8: 85416.66 | C8: 88199.102 | D8: 92250.45 | E8: 95733.004 | F8: 100457.29 | G8: 100009.37 | H8: 103170.45 | I8: 103537.18 | J8: 99012.092 | K8: 95985.377 | L8: 99297.092 | M8: 101352.94 | N8: 100253.01 | O8: 101972.57 | P8: =(O8/N8-1)*100 -> 1.7152133
A9: Déchets_radio | B9: 3546.4655 | C9: 3755.5608 | D9: 3621.3776 | E9: 4078.1305 | F9: 3706.7927 | G9: 3415.8458 | H9: 3574.7058 | I9: 3443.3398 | J9: 3451.8978 | K9: 3110.1536 | L9: 2796.9652 | M9: 3072.0631 | N9: 3274.6264 | O9: 3541.2217 | P9: =(O9/N9-1)*100 -> 8.1412432
A10: Sols et masses d'eau | B10: 38918.804 | C10: 47293.837 | D10: 56588.222 | E10: 61945.649 | F10: 67327.556 | G10: 69385.417 | H10: 71144.541 | I10: 77475.885 | J10: 86642.795 | K10: 98334.315 | L10: 111748.75 | M10: 126341.61 | N10: 139585.59 | O10: 151838.79 | P10: =(O10/N10-1)*100 -> 8.778267
A11: Bruit | B11: 6873.3078 | C11: 6613.9079 | D11: 5523.0559 | E11: 5061.1985 | F11: 5656.224 | G11: 5228.974 | H11: 4954.7266 | I11: 4666.7518 | J11: 4790.4431 | K11: 4865.702 | L11: 4590.6691 | M11: 4233.5717 | N11: 4389.3117 | O11: 5438.0457 | P11: =(O11/N11-1)*100 -> 23.892902
A12: Nature, biodiversité, paysages | B12: 22635.191 | C12: 24095.042 | D12: 24518.405 | E12: 24489.536 | F12: 25204.374 | G12: 25764.532 | H12: 25472.823 | I12: 25977.1 | J12: 26421.287 | K12: 26461.322 | L12: 28718.668 | M12: 29569.676 | N12: 31007.139 | O12: 33323.156 | P12: =(O12/N12-1)*100 -> 7.4693032
A13: Gestion des ressources naturelles | B13: =SUM(B14:B18) -> 182238.41 | C13: =SUM(C14:C18) -> 200281.25 | D13: =SUM(D14:D18) -> 230651.59 | E13: =SUM(E14:E18) -> 224234.14 | F13: =SUM(F14:F18) -> 213997.49 | G13: =SUM(G14:G18) -> 213502.43 | H13: =SUM(H14:H18) -> 208710.08 | I13: =SUM(I14:I18) -> 214738.72 | ... O13: =SUM(O14:O18) -> 285897.72 | P13: =(O13/N13-1)*100 -> 18.197329
A14: gestion_eau | B14: 3953.2821 | C14: 4415.9516 | D14: 4527.8663 | E14: 4452.7488 | F14: 4433.5072 | G14: 4209.1429 | H14: 3951.6526 | I14: 4143.4249 | J14: 4093.5378 | K14: 3981.1865 | L14: 4621.4312 | M14: 4819.5595 | N14: 3955.0359 | O14: 4508.051 | P14: =(O14/N14-1)*100 -> 13.982557
A15: gestion_forêt | B15: 11711.001 | C15: 12282.392 | D15: 11317.031 | E15: 10607.414 | F15: 10483.673 | G15: 11347.34 | H15: 10049.758 | I15: 10138.46 | J15: 9891.1794 | K15: 10641.757 | L15: 11412.265 | M15: 10288.054 | N15: 10589.88 | O15: 10484.292 | P15: =(O15/N15-1)*100 -> -0.99705895
A16: recup | B16: 24949.683 | C16: 25128.761 | D16: 25090.548 | E16: 25749.634 | F16: 26912.867 | G16: 26653.237 | H16: 26314.418 | I16: 26108.384 | J16: 26927.857 | K16: 27059.084 | L16: 27999.974 | M16: 29582.817 | N16: 28535.898 | O16: 34216.393 | P16: =(O16/N16-1)*100 -> 19.906485
A17: EnR | B17: 56744.306 | C17: 60681.215 | D17: 83468.438 | E17: 82021.735 | F17: 69723.034 | G17: 66463.756 | H17: 65486.124 | I17: 66177.755 | J17: 66582.579 | K17: 70879.508 | L17: 74593.074 | M17: 84962.244 | N17: 94942.809 | O17: 109781.22 | P17: =(O17/N17-1)*100 -> 15.628786
A18: Maîtrise énergie | B18: 84880.134 | C18: 97772.928 | D18: 106247.71 | E18: 101402.61 | F18: 102444.41 | G18: 104828.95 | H18: 102908.13 | I18: 108170.69 | J18: 108420.29 | K18: 115356.23 | L18: 114388.73 | M18: 106984.67 | N18: 103858.08 | O18: 126907.76 | P18: =(O18/N18-1)*100 -> 22.193438
A19: Activités transversales | B19: =SUM(B20:B22) -> 75511.727 | C19: =SUM(C20:C22) -> 77204.389 | D19: =SUM(D20:D22) -> 87058.252 | E19: =SUM(E20:E22) -> 89954.951 | F19: =SUM(F20:F22) -> 87085.784 | G19: =SUM(G20:G22) -> 88006.546 | H19: =SUM(H20:H22) -> 87430.253 | I19: =SUM(I20:I22) -> 84215.226 | ... O19: =SUM(O20:O22) -> 93425.512 | P19: =(O19/N19-1)*100 -> 14.683577
A20: Ingénierie | B20: 10704.822 | C20: 11244.03 | D20: 11153.752 | E20: 13305.209 | F20: 13204.098 | G20: 12693.63 | H20: 12682.798 | I20: 12467.426 | J20: 10929.747 | K20: 12097.103 | L20: 11840.699 | M20: 12536.305 | N20: 12337.622 | O20: 13652.601 | P20: =(O20/N20-1)*100 -> 10.658289
A21: R&D | B21: 20594.459 | C21: 23668.43 | D21: 23531.127 | E21: 27369.706 | F21: 27832.567 | G21: 28620.501 | H21: 28362.175 | I21: 27204.918 | J21: 25268.759 | K21: 24033.039 | L21: 22214.329 | M21: 23382.73 | N21: 23323.474 | O21: 27048.439 | P21: =(O21/N21-1)*100 -> 15.970882
A22: Serv gaux | B22: 44212.446 | C22: 42291.929 | D22: 52373.373 | E22: 49280.035 | F22: 46049.119 | G22: 46692.414 | H22: 46385.28 | I22: 44542.882 | J22: 45441.604 | K22: 44303.707 | L22: 44758.319 | M22: 45200.963 | N22: 45802.627 | O22: 52724.472 | P22: =(O22/N22-1)*100 -> 15.112331
A23: Activités périphériques | B23: =SUM(B24:B26) -> 373205.25 | C23: =SUM(C24:C26) -> 380839.32 | D23: =SUM(D24:D26) -> 378359.64 | E23: =SUM(E24:E26) -> 383874.75 | F23: =SUM(F24:F26) -> 392380.15 | G23: =SUM(G24:G26) -> 406085.78 | H23: =SUM(H24:H26) -> 407213.49 | I23: =SUM(I24:I26) -> 405081.26 | ... O23: =SUM(O24:O26) -> 422118.53 | P23: =(O23/N23-1)*100 -> 6.164493
A24: Gestion des espaces verts | B24: 22883.708 | C24: 23196.948 | D24: 23721.151 | E24: 23128.51 | F24: 24519.223 | G24: 25481.948 | H24: 27337.565 | I24: 25445.817 | J24: 27300.457 | K24: 27891.256 | L24: 29990.192 | M24: 31734.806 | N24: 35471.475 | O24: 41807.757 | P24: =(O24/N24-1)*100 -> 17.863035
A25: Transports longue distance | B25: 260459.92 | C25: 265397.48 | D25: 262742.82 | E25: 267558.47 | F25: 275071.36 | G25: 285304.16 | H25: 282749.9 | I25: 280568.99 | J25: 285811.35 | K25: 284999.23 | L25: 285440.3 | M25: 284804.43 | N25: 261110.88 | O25: 275849.29 | P25: =(O25/N25-1)*100 -> 5.6444998
A26: Transports urbains et suburbains | B26: 89861.622 | C26: 92244.892 | D26: 91895.669 | E26: 93187.772 | F26: 92789.562 | G26: 95299.677 | H26: 97126.032 | I26: 99066.454 | J26: 99544.696 | K26: 97956.861 | L26: 99460.174 | M26: 102502.34 | N26: 101025.65 | O26: 104461.49 | P26: =(O26/N26-1)*100 -> 3.4009508
A27: Total général | B27: =B4+B23 -> 856486.16 | C27: =C4+C23 -> 896032.06 | D27: =D4+D23 -> 945535.11 | E27: =E4+E23 -> 953794.22 | F27: =F4+F23 -> 958249.62 | G27: =G4+G23 -> 975859.62 | H27: =H4+H23 -> 976502.82 | I27: =I4+I23 -> 982413.52 | ... O27: =O4+O23 -> 1167759.6 | P27: =(O27/N27-1)*100 -> 9.7051136
A30: Emploi dans les éco-activités entre 2004 et 2021
A32: Domaine environnemental | B32: 2004 | C32: 2005 | D32: 2006 | E32: 2007 | F32: 2008 | G32: 2009 | H32: 2010 | I32: 2011 | J32: 2012 | K32: 2013 | L32: 2014 | M32: 2015 | N32: 2016 | O32: 2017 | P32: 2018 | Q32: 2019 | R32: 2020 | S32: 2021 | T32: Evol 2021/2004
A33: Protection des sols et des masses d'eau | B33: 31321.424 | C33: 32388.428 | D33: 34411.79 | E33: 35812.092 | F33: 38918.804 | G33: 47293.837 | H33: 56588.222 | I33: 61945.649 | J33: 67327.556 | K33: 69385.417 | L33: 71144.541 | M33: 77475.885 | N33: 86642.795 | O33: 98334.315 | P33: 111748.75 | Q33: 126341.61 | R33: 139585.59 | S33: 151838.79 | T33: =S33/B33-1 -> 3.8477614
A34: Maîtrise de l'énergie | B34: 70573.214 | C34: 74783.63 | D34: 79585.214 | E34: 84295.71 | F34: 84880.134 | G34: 97772.928 | H34: 106247.71 | I34: 101402.61 | J34: 102444.41 | K34: 104828.95 | L34: 102908.13 | M34: 108170.69 | N34: 108420.29 | O34: 115356.23 | P34: 114388.73 | Q34: 106984.67 | R34: 103858.08 | S34: 126907.76 | T34: =S34/B34-1 -> 0.79824263
A35: Energies renouvelables | B35: 32978.281 | C35: 38618.6 | D35: 43773.541 | E35: 46678.948 | F35: 56744.306 | G35: 60681.215 | H35: 83468.438 | I35: 82021.735 | J35: 69723.034 | K35: 66463.756 | L35: 65486.124 | M35: 66177.755 | N35: 66582.579 | O35: 70879.508 | P35: 74593.074 | Q35: 84962.244 | R35: 94942.809 | S35: 109781.22 | T35: =S35/B35-1 -> 2.3288944
A36: Collecte et traitement des déchets | B36: 73569.136 | C36: 77055.172 | D36: 78973.502 | E36: 82321.17 | F36: 85416.66 | G36: 88199.102 | H36: 92250.45 | I36: 95733.004 | J36: 100457.29 | K36: 100009.37 | L36: 103170.45 | M36: 103537.18 | N36: 99012.092 | O36: 95985.377 | P36: 99297.092 | Q36: 101352.94 | R36: 100253.01 | S36: 101972.57 | T36: =S36/B36-1 -> 0.3860781
A37: Gestion des eaux usées | B37: 65242.936 | C37: 67599.264 | D37: 66347.46 | E37: 66228.292 | F37: 59768.01 | G37: 60562.006 | H37: 60121.44 | I37: 58061.193 | J37: 55643.181 | K37: 57256.337 | L37: 57462.402 | M37: 55284.521 | N37: 53487.949 | O37: 54444.276 | P37: 54146.919 | Q37: 54721.273 | R37: 53488.505 | S37: 57740.51 | T37: =S37/B37-1 -> -0.11499216
A38: Administration générale relative à l'environnement | B38: 32371.867 | C38: 30919.454 | D38: 34947.436 | E38: 42094.788 | F38: 44212.446 | G38: 42291.929 | H38: 52373.373 | I38: 49280.035 | J38: 46049.119 | K38: 46692.414 | L38: 46385.28 | M38: 44542.882 | N38: 45441.604 | O38: 44303.707 | P38: 44758.319 | Q38: 45200.963 | R38: 45802.627 | S38: 52724.472 | T38: =S38/B38-1 -> 0.62871273
A39: Récupération de matériaux de recyclage | B39: 17505.178 | C39: 17893.006 | D39: 18753.904 | E39: 19274.243 | F39: 24949.683 | G39: 25128.761 | H39: 25090.548 | I39: 25749.634 | J39: 26912.867 | K39: 26653.237 | L39: 26314.418 | M39: 26108.384 | N39: 26927.857 | O39: 27059.084 | P39: 27999.974 | Q39: 29582.817 | R39: 28535.898 | S39: 34216.393 | T39: =S39/B39-1 -> 0.95464403
A40: Protection de la biodiversité et des paysages | B40: 19109.922 | C40: 19389.228 | D40: 19622.901 | E40: 20780.297 | F40: 22635.191 | G40: 24095.042 | H40: 24518.405 | I40: 24489.536 | J40: 25204.374 | K40: 25764.532 | L40: 25472.823 | M40: 25977.1 | N40: 26421.287 | O40: 26461.322 | P40: 28718.668 | Q40: 29569.676 | R40: 31007.139 | S40: 33323.156 | T40: =S40/B40-1 -> 0.74376201
A41: R & D environnementale | B41: 17399.738 | C41: 20424.047 | D41: 17489.128 | E41: 17420.771 | F41: 20594.459 | G41: 23668.43 | H41: 23531.127 | I41: 27369.706 | J41: 27832.567 | K41: 28620.501 | L41: 28362.175 | M41: 27204.918 | N41: 25268.759 | O41: 24033.039 | P41: 22214.329 | Q41: 23382.73 | R41: 23323.474 | S41: 27048.439 | T41: =S41/B41-1 -> 0.55453138
A42: Ingénierie environnementale | B42: 9402.9961 | C42: 9250.5064 | D42: 10494.474 | E42: 10864.392 | F42: 10704.822 | G42: 11244.03 | H42: 11153.752 | I42: 13305.209 | J42: 13204.098 | K42: 12693.63 | L42: 12682.798 | M42: 12467.426 | N42: 10929.747 | O42: 12097.103 | P42: 11840.699 | Q42: 12536.305 | R42: 12337.622 | S42: 13652.601 | T42: =S42/B42-1 -> 0.45194159
A43: Protection de l'air extérieur | B43: 7797.5828 | C43: 7534.3142 | D43: 7566.1988 | E43: 7629.3292 | F43: 8372.3343 | G43: 7187.6466 | H43: 6842.6751 | I43: 6361.6686 | J43: 6790.7796 | K43: 7204.3887 | L43: 7369.3422 | M43: 7993.5402 | N43: 7848.4927 | O43: 8236.7474 | P43: 9049.2129 | Q43: 9342.1265 | R43: 11501.61 | S43: 12463.59 | T43: =S43/B43-1 -> 0.59839147
A44: Gestion durable de la forêt | B44: 12243.118 | C44: 11900.681 | D44: 12084.567 | E44: 11982.838 | F44: 11711.001 | G44: 12282.392 | H44: 11317.031 | I44: 10607.414 | J44: 10483.673 | K44: 11347.34 | L44: 10049.758 | M44: 10138.46 | N44: 9891.1794 | O44: 10641.757 | P44: 11412.265 | Q44: 10288.054 | R44: 10589.88 | S44: 10484.292 | T44: =S44/B44-1 -> -0.14365831
...

Sheet graphique 3 
B2: Graphique 3 : Facteurs potentiels à l’origine des tensions dans certains métiers de l'économie verte en 2022
B34: Lecture : En 2022, l’indicateur synthétique de tension sur le marché du travail de l'économie verte dans les métiers du BTP se situe à 1,62. Il s’agit d’une moyenne de l’indicateur de tension des différents métiers du secteur du BTP par facteur de tension.
B35: Champ : France (hors Mayotte), 2022.
B36: Source : Pôle emploi – Dares, métiers en tension.
C41: Tension | D41: Intensité d'embauches | E41: Lien formation-emploi | F41: Manque de main-d'œuvre disponible | G41: Non-durabilité de l'emploi | H41: Conditions de travail contraignantes | I41: Inadéquation géographique
B42: BTP | C42: 1.6258725 | D42: 2.7508708 | E42: 0.66886453 | F42: 0.2183781 | G42: -0.31929547 | H42: -0.10483869 | I42: 0.17104321
B43: Transports, logistique | C43: 0.8355523 | D43: 0.46348299 | E43: -0.40100087 | F43: 0.72760454 | G43: -0.28484524 | H43: -0.36800272 | I43: 0.34870608

Sheet Tableau 2 
B2: Familles professionnelles | C2: Nombre de projets de recrutement | D2: Part des recrutements difficiles | E2: Tension
B3: Conducteurs routiers et grands routiers | C3: 44650 | D3: 0.727 | E3: 1.297957
B4: Ouvriers non qualifiés du second œuvre du bâtiment | C4: 37520 | D4: 0.695 | E4: 1.0303167
B5: Ouvriers non qualifiés du gros œuvre du bâtiment | C5: 37320 | D5: 0.733 | E5: 1.2144534
B6: Maçons | C6: 32130 | D6: 0.777 | E6: 1.3129754
B7: Plombiers, chauffagistes | C7: 21830 | D7: 0.806 | E7: 1.582332
B8: Menuisiers et ouvriers de l'agencement et de l'isolation | C8: 19210 | D8: 0.801 | E8: 1.6155329
B9: Conducteurs de véhicules légers (conducteurs de taxis, ambulanciers…) | C9: 18450 | D9: 0.688 | E9: 0.76810197
B10: Conducteurs de transport en commun sur route | C10: 17090 | D10: 0.808 | E10: 1.364132
B11: Électriciens du bâtiment | C11: 17040 | D11: 0.753 | E11: 1.3502192
B12: Couvreurs | C12: 13360 | D12: 0.9 | E12: 2.053378
B13: Chefs de chantier, conducteurs de travaux (non cadres) | C13: 12940 | D13: 0.748 | E13: 2.0559454
B14: Techniciens et chargés d'études du bâtiment et des travaux publics | C14: 12720 | D14: 0.681 | E14: 1.7056977
... B23: Ingénieurs et cadres des transports | C23: 380 | D23: 0.553 | E23: 1.0954689
B24: Ensemble des métiers de l'économie verte | C24: 539520 | D24: 0.665 | E24: -
B25: Ensemble des 200 métiers | C25: 3046350 | D25: 0.579 | E25: -
B27: Champ : le périmètre de l'enquête « Besoin en main-d’œuvre » (BMO) porte sur 200 FAP (sur les 225 que compte la nomenclature). France – focus sur le secteur du bâtiment et travaux publics et celui du transport et de la logistique.
B28: Lecture : en 2022, l’indicateur synthétique de tension sur le marché du travail de l’économie verte, pour le métier de couvreur se situe à 2,053.
B29: Source : Les sources de données mobilisées sont l’enquête « Besoin en main-d’œuvre » de Pôle emploi et les indicateurs de tension produits par la Dares et Pôle emploi.
