Workbook
Name _016: #REF!
Name _016: #REF!
Name _016: #REF!
Name test: #REF!

Sheet Sommaire
A1: Bilan environnemental
A4: Fiche 18: Consommation de matières et empreinte matières
A8: Sommaire
A10: Donnees | C10: Ensemble des données à compléter et mettre à jour. Le reste des feuilles excel seont automatisées.
A13: Graph 1 | C13: Graphique 1: extraction, importation et exportation de matière en France.
A16: Graph 2 | C16: Graphique 2: PIB et consommation de matières.
A19: Graph 3 | C19: Graphique 3: Evolution de la consommation de matière et de la productivité de matière de l'économie française.
A22: Graph 4 | C22: Graphique 4: Comparaison internationale de la consommation de matières. Pas de mis-à-jour ou automatisation pour l'instant.

Sheet Donnees_Eurostat_MFA
A1: Ensemble des données EUROSTAT à compléter et mettre à jour
A6: https://ec.europa.eu/eurostat/databrowser/view/ENV_AC_MFA__custom_7190444/default/table?lang=fr
A7: Données extraites le18/08/2023 10:26:03 depuis [ESTAT]
A8: Dataset: | B8: Comptes de flux de matières [ENV_AC_MFA__custom_7190444]
A9: Dernière mise à jour: | B9: 17/07/2023 11:00
A11: Fréquence (relative au temps) | C11: Annuel
A12: Unité de mesure | C12: Mille tonnes
A13: Entité géopolitique (déclarante) | C13: France
A15: TIME | B15: TIME | C15: 1990 | D15: 1991 | E15: 1992 | F15: 1993 | G15: 1994 | H15: 1995 | I15: 1996 | J15: 1997 | K15: 1998 | L15: 1999 | M15: 2000 | N15: 2001 | O15: 2002 | P15: 2003 | Q15: 2004 | R15: 2005 | S15: 2006 | T15: 2007 | U15: 2008 | V15: 2009 | W15: 2010 | X15: 2011 | Y15: 2012 | Z15: 2013 | AA15: 2014 | AB15: 2015 | AC15: 2016 | AD15: 2017 | AE15: 2018 | AF15: 2019 | AG15: 2020 | AH15: 2021 | AI15: 2022
A16: INDIC_ENV (Libellés) | B16: MATERIAL (Libellés)
A17: Extraction intérieure | B17: Total | C17: 709034.8 | D17: 720334.65 | E17: 708009.58 | F17: 662697.15 | G17: 680576.25 | H17: 672150.61 | I17: 643625.25 | J17: 663530.64 | K17: 676517.3 | L17: 701724.43 | M17: 735010.91 | N17: 705066.14 | O17: 705622.71 | P17: 656750.51 | Q17: 713829.74 | R17: 689755.13 | S17: 704777.94 | T17: 737208.61 | U17: 719407.48 | V17: 659054.65 | W17: 636404.28 | X17: 654972.22 | Y17: 634447.5 | Z17: 636331.51 | AA17: 639682.09 | AB17: 594668.75 | AC17: 578366.89 | AD17: 630285.07 | AE17: 623726.38 | AF17: 647763.93 | AG17: 590064.04 | AH17: 649623.65 | AI17: 627353.21
B18: Biomasse | C18: 236827.32 | D18: 243836.76 | E18: 266618.94 | F18: 251950.49 | G18: 247033.7 | H18: 240276.26 | I18: 244540.95 | J18: 256853.3 | K18: 261578.56 | L18: 269260.94 | M18: 280858.2 | N18: 256584.71 | O18: 272341.59 | P18: 223199.05 | Q18: 273084.27 | R18: 250847.45 | S18: 249897.82 | T18: 268537.19 | U18: 272155.75 | V18: 269510.77 | W18: 255619.94 | X18: 257340.04 | Y18: 263887.15 | Z18: 262402.42 | AA18: 286930.05 | AB18: 257101.36 | AC18: 237910.88 | AD18: 274132.09 | AE18: 249869.07 | AF18: 253574.86 | AG18: 226381.69 | AH18: 254157.35 | AI18: 226778.4
B19: Cultures (à l'exclusion des cultures fourragères) | C19: 120866.39 | D19: 121640.25 | E19: 128078.41 | F19: 120052.58 | G19: 115789.78 | H19: 118114.61 | I19: 128809.7 | J19: 133686.2 | K19: 133965.15 | L19: 135544.15 | M19: 133187.98 | N19: 121011.54 | O19: 138595.83 | P19: 117645.18 | Q19: 138454.02 | R19: 130649.99 | S19: 125328.94 | T19: 126002.83 | U19: 133330.6 | V19: 140083.06 | W19: 131176.77 | X19: 136697.28 | Y19: 134077.61 | Z19: 131506 | AA19: 145093.05 | AB19: 139926.3 | AC19: 121189.74 | AD19: 149431.24 | AE19: 135766.05 | AF19: 141769.18 | AG19: 116330.83 | AH19: 133282.54 | AI19: :
B20: Céréales | C20: 55078.886 | D20: 60260.618 | E20: 60471.705 | F20: 55417.733 | G20: 53184.197 | H20: 53293.581 | I20: 62269.382 | J20: 63043.519 | K20: 67946.452 | L20: 64259.092 | M20: 65720.413 | N20: 60284.239 | O20: 69639.816 | P20: 55005.669 | Q20: 70522.398 | R20: 64098.208 | S20: 61741.162 | T20: 60144.44 | U20: 70284.032 | V20: 70080.042 | W20: 65505.899 | X20: 63826.02 | Y20: 68460.426 | Z20: 67343 | AA20: 72431.158 | AB20: 72716.323 | AC20: 54190.536 | AD20: 68525.433 | AE20: 62565.273 | AF20: 71206.258 | AG20: 57709.045 | AH20: 67616.753 | AI20: :
B21: Racines, tubercules | C21: 4722.81 | D21: 5406.975 | E21: 6567.803 | F21: 5731.178 | G21: 5377.075 | H21: 5752.291 | I21: 6104.255 | J21: 6513.006 | K21: 5908.28 | L21: 6534.363 | M21: 6440.483 | N21: 6049.646 | O21: 6874.391 | P21: 6355.131 | Q21: 7255.378 | R21: 6604.6 | S21: 6362.823 | T21: 7209.931 | U21: 6913.369 | V21: 7134.522 | W21: 6709.065 | X21: 7480.877 | Y21: 6378.264 | Z21: 7033 | AA21: 8167.738 | AB21: 7210.255 | AC21: 7067.389 | AD21: 8609.681 | AE21: 7924.184 | AF21: 8622.128 | AG21: 8874.242 | AH21: 8982.668 | AI21: :
B22: Cultures sucrières | C22: 34068.711 | D22: 32286.167 | E22: 34257.426 | F22: 34359.208 | G22: 31404.061 | H22: 32838.472 | I22: 33570.536 | J22: 36783.558 | K22: 33179.68 | L22: 35441.083 | M22: 33975.133 | N22: 29499.772 | O22: 36307.265 | P22: 32106.513 | Q22: 33929.694 | R22: 34105.806 | S22: 32727.111 | T22: 35852.692 | U22: 33121.8 | V22: 38090.131 | W22: 34835.086 | X22: 40150.957 | Y22: 36272.907 | Z22: 36050 | AA22: 40476.337 | AB22: 36289.91 | AC22: 37198.362 | AD22: 49175 | AE22: 42202.575 | AF22: 40505.268 | AG22: 28494.547 | AH22: 36765.474 | AI22: :
B23: Légumineuses | C23: 3709.995 | D23: 3284.7 | E23: 3337.024 | F23: 3809.421 | G23: 3472.673 | H23: 2845.195 | I23: 2669.301 | J23: 3222.996 | K23: 3435.932 | L23: 2818.133 | M23: 2094.976 | N23: 1867.622 | O23: 2025.03 | P23: 1934.749 | Q23: 2085.425 | R23: 1747.481 | S23: 1345.309 | T23: 867.721 | U23: 783.116 | V23: 999.796 | W23: 1594.869 | X23: 1045.491 | Y23: 881.539 | Z23: 771 | AA23: 862.205 | AB23: 974.729 | AC23: 807.93 | AD23: 1059.421 | AE23: 801.139 | AF23: 949.018 | AG23: 750.02 | AH23: 782.764 | AI23: :
B24: Noix | C24: 45.187 | D24: 35.673 | E24: 42.86 | F24: 34.188 | G24: 43.598 | H24: 37.84 | I24: 38.739 | J24: 40.21 | K24: 43.235 | L24: 47.243 | M24: 46.935 | N24: 44.526 | O24: 52.149 | P24: 39.276 | Q24: 47.817 | R24: 50.796 | S24: 61.21 | T24: 47.882 | U24: 49.398 | V24: 40.732 | W24: 50.981 | X24: 53.333 | Y24: 59.125 | Z24: 53 | AA24: 55.555 | AB24: 59.913 | AC24: 61.984 | AD24: 50.525 | AE24: 63.178 | AF24: 55.086 | AG24: 61.513 | AH24: 64.305 | AI24: :
B25: Cultures oléagineuses | C25: 4564.1 | D25: 5079.52 | E25: 4094.725 | F25: 3492.842 | G25: 4296.187 | H25: 5017.095 | I25: 5181.468 | J25: 5775.765 | K25: 5759.146 | L25: 6636.298 | M25: 5558.243 | N25: 4809.458 | O25: 5058.971 | P25: 5060.844 | Q25: 5630.207 | R25: 6232.332 | S25: 5768.919 | T25: 6146.479 | U25: 6434.097 | V25: 7481.036 | W25: 6666.528 | X25: 7442.833 | Y25: 7233.532 | Z25: 6122 | AA25: 7392.204 | AB25: 6951.738 | AC25: 6332.506 | AD25: 7434.164 | AE25: 6708.735 | AF25: 5334.555 | AG25: 5406.878 | AH25: 5752.981 | AI25: :
B26: Légumes | C26: 5559.936 | D26: 5909.875 | E26: 5685.003 | F26: 5757.505 | G26: 5834.433 | H26: 6025.248 | I26: 6127.33 | J26: 6108.95 | K26: 6254.495 | L26: 6437.646 | M26: 6313.892 | N26: 6349.141 | O26: 6523.333 | P26: 6234.149 | Q26: 6376.273 | R26: 5989.275 | S26: 5805.884 | T26: 5482.445 | U26: 5787.251 | V26: 5552.435 | W26: 5594.373 | X26: 5804.482 | Y26: 5403.867 | Z26: 4895 | AA26: 5395.128 | AB26: 5332.144 | AC26: 5376.327 | AD26: 5582.479 | AE26: 5260.711 | AF26: 5448.604 | AG26: 5158.371 | AH26: 5228.48 | AI26: :
B27: Fruits | C27: 12586.625 | D27: 8962.763 | E27: 13242.996 | F27: 10981.567 | G27: 11684.526 | H27: 11808.199 | I27: 12380.716 | J27: 11695.189 | K27: 10959.219 | L27: 12821.06 | M27: 12450.268 | N27: 11627.556 | O27: 11426.283 | P27: 10178.965 | Q27: 11800.439 | R27: 10999.313 | S27: 10822.95 | T27: 9651.233 | U27: 9205.273 | V27: 10024.317 | W27: 9661.796 | X27: 10403.574 | Y27: 8738.141 | Z27: 8631 | AA27: 9642.573 | AB27: 9766.392 | AC27: 9438.609 | AD27: 8250.815 | AE27: 9378.797 | AF27: 8678.385 | AG27: 8833.549 | AH27: 7073.108 | AI27: :
B28: Fibres | C28: 364.916 | D28: 267.471 | E28: 188.86 | F28: 223.034 | G28: 310.611 | H28: 327.974 | I28: 285.098 | J28: 314.855 | K28: 286.786 | L28: 343.062 | M28: 373.817 | N28: 285.767 | O28: 490.128 | P28: 535.796 | Q28: 546.472 | R28: 593.314 | S28: 531.323 | T28: 471.834 | U28: 608.998 | V28: 492.037 | W28: 427.651 | X28: 339.213 | Y28: 543.027 | Z28: 509 | AA28: 577.311 | AB28: 566.444 | AC28: 657.581 | AD28: 684.805 | AE28: 776.274 | AF28: 905.823 | AG28: 850.556 | AH28: 821.238 | AI28: :
B29: Autres cultures (à l'exclusion des cultures fourragères) n.c.a. | C29: 165.226 | D29: 146.486 | E29: 190.008 | F29: 245.906 | G29: 182.419 | H29: 168.712 | I29: 182.876 | J29: 188.156 | K29: 191.921 | L29: 206.175 | M29: 213.825 | N29: 193.815 | O29: 198.466 | P29: 194.086 | Q29: 259.918 | R29: 228.869 | S29: 162.251 | T29: 128.178 | U29: 143.264 | V29: 188.014 | W29: 130.523 | X29: 150.501 | Y29: 106.786 | Z29: 99 | AA29: 92.836 | AB29: 58.454 | AC29: 58.516 | AD29: 58.917 | AE29: 85.18 | AF29: 64.056 | AG29: 192.108 | AH29: 194.768 | AI29: :
B30: Résidus de cultures (utilisés), cultures fourragères et biomasse pâturée | C30: 87180.168 | D30: 94048.947 | E30: 111302.81 | F30: 106984 | G30: 104422.27 | H30: 94620.339 | I30: 90261.076 | J30: 96577.537 | K30: 100649.03 | L30: 106369.15 | M30: 113143.99 | N30: 105662.46 | O30: 107305.8 | P30: 80922.67 | Q30: 109494.54 | R30: 94603.629 | S30: 98773.446 | T30: 115851.54 | U30: 113643.31 | V30: 102751.34 | W30: 96964.688 | X30: 93510.513 | Y30: 105125.79 | Z30: 105603.97 | AA30: 115217.7 | AB30: 95425.958 | AC30: 94616.175 | AD30: 102248.13 | AE30: 91266.906 | AF30: 89503.91 | AG30: 88670.327 | AH30: 97719.858 | AI30: :
... B43: Chasse et cueillette | C43: 41.918 | D43: 44.23 | E43: 46.427 | F43: 50.329 | G43: 52.145 | H43: 54.978 | I43: 61.481 | J43: 65.029 | K43: 68.071 | L43: 65.438 | M43: 72.918 | N43: 74.34 | O43: 79.796 | P43: 83.542 | Q43: 81.275 | R43: 81.193 | S43: 83.271 | T43: 88.27 | U43: 92.247 | V43: 85.666 | W43: 91.817 | X43: 90.039 | Y43: 97.623 | Z43: 93.11 | AA43: 96.128 | AB43: 103.89 | AC43: 106.968 | AD43: 113.056 | AE43: 112.271 | AF43: 117.987 | AG43: 117.234 | AH43: 122.046 | AI43: :
B44: Animaux vivants et produits animaux (autres que poisson sauvage, animaux/plantes aquatiques, chasse et cueillette) | AI44: :
B45: Animaux vivants (autres que poisson sauvage, animaux/plantes aquatiques, chasse et cueillette) | AI45: :
B46: Viandes et préparations de viande | AI46: :
B47: Produits laitiers, oeufs d'oiseaux et miel | AI47: :
B48: Autres produits d'animaux (fibres animales, peaux, fourrures, cuir, etc.) | AI48: :
B49: Produits essentiellement à base de biomasse | AI49: :
B50: Minerais métalliques (minerais bruts) | C50: 13150.787 | D50: 10715.168 | E50: 7955.429 | F50: 5174.344 | G50: 3559.485 | H50: 2326.122 | I50: 1836.102 | J50: 740.74 | K50: 214.866 | L50: 233.415 | M50: 216.979 | N50: 173.569 | O50: 116.082 | P50: 98.112 | Q50: 97.875 | R50: 106.4 | S50: 127.8 | T50: 126.874 | U50: 112.97 | V50: 145.947 | W50: 155.256 | X50: 99.479 | Y50: 66.617 | Z50: 175.954 | AA50: 119.194 | AB50: 96.504 | AC50: 165.235 | AD50: 212.084 | AE50: 186.331 | AF50: 193.337 | AG50: 207.984 | AH50: 236.508 | AI50: 236.508
B51: Fer | C51: 11370 | D51: 9747 | E51: 7288 | F51: 4543 | G51: 3118 | H51: 1967 | I51: 1460 | J51: 523 | K51: 21 | L51: 23 | M51: 31 | N51: 37 | O51: 21 | P51: 0 | Q51: 0 | R51: 0 | S51: 0 | T51: 0 | U51: 0 | V51: 0 | W51: 0 | X51: 0 | Y51: 0 | Z51: 0.97 | AA51: 0.443 | AB51: 3.358 | AC51: 14.237 | AD51: 15.138 | AE51: 23.119 | AF51: 24.421 | AG51: 21.734 | AH51: 12.631 | AI51: :
B52: Métaux non ferreux | C52: 1780.787 | D52: 968.168 | E52: 667.429 | F52: 631.344 | G52: 441.485 | H52: 359.122 | I52: 376.102 | J52: 217.74 | K52: 193.866 | L52: 210.415 | M52: 185.979 | N52: 136.569 | O52: 95.082 | P52: 98.112 | Q52: 97.875 | R52: 106.4 | S52: 127.8 | T52: 126.874 | U52: 112.97 | V52: 145.947 | W52: 155.256 | X52: 99.479 | Y52: 66.617 | Z52: 174.984 | AA52: 118.751 | AB52: 93.146 | AC52: 150.998 | AD52: 196.946 | AE52: 163.212 | AF52: 168.915 | AG52: 186.25 | AH52: 223.877 | AI52: :
B53: Cuivre | C53: 0.911 | D53: 0.689 | E53: 0.543 | F53: 0 | G53: 0 | H53: 0 | I53: 0 | J53: 0 | K53: 0 | L53: 0 | M53: 0 | N53: 0 | O53: 0 | P53: 0 | Q53: 0 | R53: 0 | S53: 0 | T53: 0 | U53: 0 | V53: 0 | W53: 0 | X53: 0 | Y53: 0 | Z53: 0 | AA53: 0 | AB53: 0 | AC53: 0 | AD53: 0 | AE53: 0 | AF53: 0 | AG53: 0 | AH53: 0 | AI53: :
B54: Nickel | C54: 0 | D54: 0 | E54: 0 | F54: 0 | G54: 0 | H54: 0 | I54: 0 | J54: 0 | K54: 0 | L54: 0 | M54: 0 | N54: 0 | O54: 0 | P54: 0 | Q54: 0 | R54: 0 | S54: 0 | T54: 0 | U54: 0 | V54: 0 | W54: 0 | X54: 0 | Y54: 0 | Z54: 0 | AA54: 0 | AB54: 0 | AC54: 0 | AD54: 0 | AE54: 0 | AF54: 0 | AG54: 0 | AH54: 0 | AI54: :
B55: Plomb | C55: 1.766 | D55: 2.043 | E55: 0 | F55: 0 | G55: 0 | H55: 0 | I55: 0 | J55: 0 | K55: 0 | L55: 0 | M55: 0 | N55: 0 | O55: 0 | P55: 0 | Q55: 0 | R55: 0 | S55: 0 | T55: 0 | U55: 0 | V55: 0 | W55: 0 | X55: 0 | Y55: 0 | Z55: 0 | AA55: 0 | AB55: 0 | AC55: 0 | AD55: 0 | AE55: 0 | AF55: 0 | AG55: 0 | AH55: 0 | AI55: :
B56: Zinc | C56: 42.826 | D56: 48.982 | E56: 29.376 | F56: 24.284 | G56: 0 | H56: 0 | I56: 0 | J56: 0 | K56: 0 | L56: 0 | M56: 0 | N56: 0 | O56: 0 | P56: 0 | Q56: 0 | R56: 0 | S56: 0 | T56: 0 | U56: 0 | V56: 0 | W56: 0 | X56: 0 | Y56: 0 | Z56: 0 | AA56: 0 | AB56: 0 | AC56: 0 | AD56: 0 | AE56: 0 | AF56: 0 | AG56: 0 | AH56: 0 | AI56: :
B57: Étain | C57: 0 | D57: 0 | E57: 0 | F57: 0 | G57: 0 | H57: 0 | I57: 0 | J57: 0 | K57: 0 | L57: 0 | M57: 0 | N57: 0 | O57: 0 | P57: 0 | Q57: 0 | R57: 0 | S57: 0 | T57: 0 | U57: 0 | V57: 0 | W57: 0 | X57: 0 | Y57: 0 | Z57: 0 | AA57: 0 | AB57: 0 | AC57: 0 | AD57: 0 | AE57: 0 | AF57: 0 | AG57: 0 | AH57: 0 | AI57: :
B58: Or, argent, platine et autres métaux précieux | C58: 44.197 | D58: 34.549 | E58: 7.82 | F58: 6.06 | G58: 9.484 | H58: 10.99 | I58: 9.404 | J58: 9.172 | K58: 7.942 | L58: 7.631 | M58: 7.853 | N58: 7.658 | O58: 5.182 | P58: 5.012 | Q58: 4.475 | R58: 0 | S58: 0 | T58: 0 | AI58: :
...

Sheet Donnees_Eurostat_MF
A1: Empreinte matières de la France
A5: https://ec.europa.eu/eurostat/databrowser/view/ENV_AC_RME/default/table?lang=en
A6: Données extraites le16/08/2023 17:50:25 depuis [ESTAT]
A7: Dataset: | B7: Empreinte matières - indicateurs principaux [ENV_AC_RME__custom_7176053]
A8: Dernière mise à jour: | B8: 17/07/2023 11:00
A10: Fréquence (relative au temps) | B10: Annuel
A11: Entité géopolitique (déclarante) | B11: France
A13: TIME | B13: TIME | C13: 2008 | D13: 2008 | E13: 2009 | F13: 2009 | G13: 2010 | H13: 2010 | I13: 2011 | J13: 2011 | K13: 2012 | L13: 2012 | M13: 2013 | N13: 2013 | O13: 2014 | P13: 2014 | Q13: 2015 | R13: 2015 | S13: 2016 | T13: 2016 | U13: 2017 | V13: 2017 | W13: 2018 | X13: 2018 | Y13: 2019 | Z13: 2019 | AA13: 2020 | AB13: 2020
A14: UNIT (Libellés) | B14: UNIT (Libellés) | C14: Mille tonnes | D14: Tonnes par personne | E14: Mille tonnes | F14: Tonnes par personne | G14: Mille tonnes | H14: Tonnes par personne | I14: Mille tonnes | J14: Tonnes par personne | K14: Mille tonnes | L14: Tonnes par personne | M14: Mille tonnes | N14: Tonnes par personne | O14: Mille tonnes | P14: Tonnes par personne | Q14: Mille tonnes | R14: Tonnes par personne | S14: Mille tonnes | T14: Tonnes par personne | U14: Mille tonnes | V14: Tonnes par personne | W14: Mille tonnes | X14: Tonnes par personne | Y14: Mille tonnes | Z14: Tonnes par personne | AA14: Mille tonnes | AB14: Tonnes par personne
A15: INDIC_ENV (Libellés) | B15: MATERIAL (Libellés)
A16: Extraction intérieure | B16: Total | C16: 719407.48 | D16: 11.209 | E16: 659054.65 | F16: 10.217 | G16: 636404.28 | H16: 9.818 | I16: 654972.22 | J16: 10.057 | K16: 634447.5 | L16: 9.695 | M16: 636331.51 | N16: 9.675 | O16: 639682.09 | P16: 9.647 | Q16: 594668.75 | R16: 8.936 | S16: 578366.89 | T16: 8.668 | U16: 630285.07 | V16: 9.419 | W16: 623726.38 | X16: 9.287 | Y16: 647763.93 | Z16: 9.612 | AA16: 590064.04 | AB16: 8.732
B17: Biomasse | C17: 272155.75 | D17: 4.241 | E17: 269510.77 | F17: 4.178 | G17: 255619.94 | H17: 3.944 | I17: 257340.04 | J17: 3.951 | K17: 263887.15 | L17: 4.033 | M17: 262402.42 | N17: 3.99 | O17: 286930.05 | P17: 4.327 | Q17: 257101.36 | R17: 3.863 | S17: 237910.88 | T17: 3.566 | U17: 274132.09 | V17: 4.097 | W17: 249869.07 | X17: 3.721 | Y17: 253574.86 | Z17: 3.763 | AA17: 226381.69 | AB17: 3.35
B18: Minerais métalliques (minerais bruts) | C18: 112.97 | D18: 0.002 | E18: 145.947 | F18: 0.002 | G18: 155.256 | H18: 0.002 | I18: 99.479 | J18: 0.002 | K18: 66.617 | L18: 0.001 | M18: 175.954 | N18: 0.003 | O18: 119.194 | P18: 0.002 | Q18: 96.504 | R18: 0.001 | S18: 165.235 | T18: 0.002 | U18: 212.084 | V18: 0.003 | W18: 186.331 | X18: 0.003 | Y18: 193.337 | Z18: 0.003 | AA18: 207.984 | AB18: 0.003
B19: Minerais non métalliques | C19: 445117.17 | D19: 6.936 | E19: 387623.13 | F19: 6.009 | G19: 378850.48 | H19: 5.845 | I19: 396037.94 | J19: 6.081 | K19: 368994.04 | L19: 5.639 | M19: 372392.26 | N19: 5.662 | O19: 351551.69 | P19: 5.301 | Q19: 336623.83 | R19: 5.058 | S19: 339458.74 | T19: 5.087 | U19: 355170.29 | V19: 5.308 | W19: 372888.08 | X19: 5.552 | Y19: 393262.95 | Z19: 5.836 | AA19: 362814.49 | AB19: 5.369
B20: Matières/vecteurs énergétiques fossiles | C20: 2021.6 | D20: 0.031 | E20: 1774.8 | F20: 0.028 | G20: 1778.6 | H20: 0.027 | I20: 1494.764 | J20: 0.023 | K20: 1499.697 | L20: 0.023 | M20: 1360.872 | N20: 0.021 | O20: 1081.163 | P20: 0.016 | Q20: 847.058 | R20: 0.013 | S20: 832.033 | T20: 0.012 | U20: 770.605 | V20: 0.012 | W20: 782.906 | X20: 0.012 | Y20: 732.788 | Z20: 0.011 | AA20: 659.879 | AB20: 0.01
A21: Importations en équivalent matières premières | B21: Total | C21: 929858.65 | D21: 14.489 | E21: 843726.72 | F21: 13.08 | G21: 732633.76 | H21: 11.303 | I21: 764468.12 | J21: 11.738 | K21: 732955.68 | L21: 11.201 | M21: 742805.78 | N21: 11.294 | O21: 745678.18 | P21: 11.245 | Q21: 745287.62 | R21: 11.199 | S21: 743185.25 | T21: 11.138 | U21: 821723.33 | V21: 12.28 | W21: 816273.41 | X21: 12.154 | Y21: 807342.53 | Z21: 11.981 | AA21: 732206.06 | AB21: 10.836
B22: Biomasse | C22: 84408.635 | D22: 1.315 | E22: 79848.503 | F22: 1.238 | G22: 77062.485 | H22: 1.189 | I22: 80085.294 | J22: 1.23 | K22: 76876.299 | L22: 1.175 | M22: 81290.011 | N22: 1.236 | O22: 85626.486 | P22: 1.291 | Q22: 81287.203 | R22: 1.221 | S22: 84043.808 | T22: 1.26 | U22: 87895.28 | V22: 1.313 | W22: 87005.506 | X22: 1.296 | Y22: 90036.696 | Z22: 1.336 | AA22: 92397.409 | AB22: 1.367
B23: Minerais métalliques (minerais bruts) | C23: 285086.18 | D23: 4.442 | E23: 174509.26 | F23: 2.705 | G23: 208052.58 | H23: 3.21 | I23: 207411.5 | J23: 3.185 | K23: 191891.87 | L23: 2.932 | M23: 197465.49 | N23: 3.002 | O23: 210447.24 | P23: 3.174 | Q23: 197280.5 | R23: 2.964 | S23: 206406.44 | T23: 3.093 | U23: 222563.14 | V23: 3.326 | W23: 238431.2 | X23: 3.55 | Y23: 210341.38 | Z23: 3.121 | AA23: 193646.36 | AB23: 2.866
B24: Minerais non métalliques | C24: 188993.68 | D24: 2.945 | E24: 202688.21 | F24: 3.142 | G24: 147255.47 | H24: 2.272 | I24: 167464.9 | J24: 2.571 | K24: 152687.27 | L24: 2.333 | M24: 144537.04 | N24: 2.198 | O24: 139103.61 | P24: 2.098 | Q24: 147671.38 | R24: 2.219 | S24: 141617.03 | T24: 2.122 | U24: 201232.57 | V24: 3.007 | W24: 186656.87 | X24: 2.779 | Y24: 204757.3 | Z24: 3.038 | AA24: 191279.88 | AB24: 2.831
B25: Matières/vecteurs énergétiques fossiles | C25: 371370.15 | D25: 5.787 | E25: 386680.74 | F25: 5.995 | G25: 300263.22 | H25: 4.632 | I25: 309506.43 | J25: 4.752 | K25: 311500.24 | L25: 4.76 | M25: 319513.24 | N25: 4.858 | O25: 310500.84 | P25: 4.682 | Q25: 319048.54 | R25: 4.794 | S25: 311117.97 | T25: 4.663 | U25: 310032.34 | V25: 4.633 | W25: 304179.84 | X25: 4.529 | Y25: 302207.16 | Z25: 4.485 | AA25: 254882.42 | AB25: 3.772
A26: Exportations en équivalent matières premières | B26: Total | C26: 572298.02 | D26: 8.917 | E26: 512847.39 | F26: 7.951 | G26: 486334.64 | H26: 7.503 | I26: 504714.38 | J26: 7.75 | K26: 472508.38 | L26: 7.221 | M26: 479685.97 | N26: 7.293 | O26: 483313.4 | P26: 7.288 | Q26: 491134.18 | R26: 7.38 | S26: 471557.74 | T26: 7.067 | U26: 530660.7 | V26: 7.93 | W26: 521976.82 | X26: 7.772 | Y26: 526084.58 | Z26: 7.807 | AA26: 464153.39 | AB26: 6.869
B27: Biomasse | C27: 98473.671 | D27: 1.534 | E27: 96339.124 | F27: 1.494 | G27: 120290.23 | H27: 1.856 | I27: 121549.89 | J27: 1.866 | K27: 112370.8 | L27: 1.717 | M27: 118659.46 | N27: 1.804 | O27: 122329.7 | P27: 1.845 | Q27: 121067.05 | R27: 1.819 | S27: 114685.29 | T27: 1.719 | U27: 112874.44 | V27: 1.687 | W27: 116770.19 | X27: 1.739 | Y27: 118917.85 | Z27: 1.765 | AA27: 115997.13 | AB27: 1.717
B28: Minerais métalliques (minerais bruts) | C28: 175188.19 | D28: 2.73 | E28: 113878.52 | F28: 1.765 | G28: 127864.17 | H28: 1.973 | I28: 126295.9 | J28: 1.939 | K28: 117937.71 | L28: 1.802 | M28: 122840.41 | N28: 1.868 | O28: 125765.54 | P28: 1.897 | Q28: 122969.73 | R28: 1.848 | S28: 122890.57 | T28: 1.842 | U28: 133375.01 | V28: 1.993 | W28: 134100.51 | X28: 1.997 | Y28: 122708.89 | Z28: 1.821 | AA28: 107837.57 | AB28: 1.596
B29: Minerais non métalliques | C29: 145391.87 | D29: 2.265 | E29: 154339.51 | F29: 2.393 | G29: 120424.6 | H29: 1.858 | I29: 132665.02 | J29: 2.037 | K29: 121050.57 | L29: 1.85 | M29: 114341.78 | N29: 1.738 | O29: 111137.85 | P29: 1.676 | Q29: 118795.85 | R29: 1.785 | S29: 110486.34 | T29: 1.656 | U29: 159258.62 | V29: 2.38 | W29: 146608.58 | X29: 2.183 | Y29: 160412.89 | Z29: 2.38 | AA29: 141913.51 | AB29: 2.1
B30: Matières/vecteurs énergétiques fossiles | C30: 153244.28 | D30: 2.388 | E30: 148290.24 | F30: 2.299 | G30: 117755.64 | H30: 1.817 | I30: 124203.57 | J30: 1.907 | K30: 121149.3 | L30: 1.851 | M30: 123844.32 | N30: 1.883 | O30: 124080.31 | P30: 1.871 | Q30: 128301.56 | R30: 1.928 | S30: 123495.54 | T30: 1.851 | U30: 125152.63 | V30: 1.87 | W30: 124497.54 | X30: 1.854 | Y30: 124044.95 | Z30: 1.841 | AA30: 98405.183 | AB30: 1.456
A31: Consommation de matières premières | B31: Total | C31: 1076968.1 | D31: 16.781 | E31: 989933.98 | F31: 15.347 | G31: 882703.4 | H31: 13.618 | I31: 914725.96 | J31: 14.045 | K31: 894894.8 | L31: 13.675 | M31: 899451.32 | N31: 13.675 | O31: 902046.87 | P31: 13.603 | Q31: 848822.19 | R31: 12.755 | S31: 849994.41 | T31: 12.739 | U31: 921347.71 | V31: 13.768 | W31: 918022.97 | X31: 13.67 | Y31: 929021.88 | Z31: 13.786 | AA31: 858116.72 | AB31: 12.699
B32: Biomasse | C32: 258090.71 | D32: 4.021 | E32: 253020.15 | F32: 3.923 | G32: 212392.2 | H32: 3.277 | I32: 215875.45 | J32: 3.315 | K32: 228392.65 | L32: 3.49 | M32: 225032.97 | N32: 3.421 | O32: 250226.83 | P32: 3.773 | Q32: 217321.52 | R32: 3.266 | S32: 207269.4 | T32: 3.106 | U32: 249152.93 | V32: 3.723 | W32: 220104.38 | X32: 3.277 | Y32: 224693.71 | Z32: 3.334 | AA32: 202781.97 | AB32: 3.001
B33: Minerais métalliques (minerais bruts) | C33: 110010.96 | D33: 1.714 | E33: 60776.689 | F33: 0.942 | G33: 80343.666 | H33: 1.24 | I33: 81215.076 | J33: 1.247 | K33: 74020.776 | L33: 1.131 | M33: 74801.033 | N33: 1.137 | O33: 84800.895 | P33: 1.279 | Q33: 74407.277 | R33: 1.118 | S33: 83681.109 | T33: 1.254 | U33: 89400.221 | V33: 1.336 | W33: 104517.01 | X33: 1.556 | Y33: 87825.82 | Z33: 1.303 | AA33: 86016.777 | AB33: 1.273
B34: Minerais non métalliques | C34: 488718.98 | D34: 7.615 | E34: 435971.83 | F34: 6.759 | G34: 405681.35 | H34: 6.259 | I34: 430837.82 | J34: 6.615 | K34: 400630.74 | L34: 6.122 | M34: 402587.52 | N34: 6.121 | O34: 379517.45 | P34: 5.723 | Q34: 365499.36 | R34: 5.492 | S34: 370589.43 | T34: 5.554 | U34: 397144.23 | V34: 5.935 | W34: 412936.36 | X34: 6.149 | Y34: 437607.36 | Z34: 6.494 | AA34: 412180.86 | AB34: 6.1
B35: Matières/vecteurs énergétiques fossiles | C35: 220147.46 | D35: 3.43 | E35: 240165.31 | F35: 3.723 | G35: 184286.18 | H35: 2.843 | I35: 186797.62 | J35: 2.868 | K35: 191850.63 | L35: 2.932 | M35: 197029.79 | N35: 2.996 | O35: 187501.69 | P35: 2.828 | Q35: 191594.04 | R35: 2.879 | S35: 188454.47 | T35: 2.824 | U35: 185650.32 | V35: 2.774 | W35: 180465.21 | X35: 2.687 | Y35: 178895 | Z35: 2.655 | AA35: 157137.11 | AB35: 2.326
A37: Valeur spéciale
A38: : | B38: Non disponible

Sheet Donnees_INSEE
A1: Ensemble des données INSEE à compléter et mettre à jour
A6: https://www.insee.fr/fr/statistiques/5225246#tableau-figure1
A7: Données extraites le 18/08/2023 10:26:03 depuis le site de l'INSEE
A8: Dataset: | B8: Population au 1er janvier
A9: Dernière mise à jour: | B9: 44943
A11: Fréquence (relative au temps) | C11: Annuel
A12: Unité de mesure | C12: nombre d'habitants
A15: Année | B15: 1990 | C15: 1991 | D15: 1992 | E15: 1993 | F15: 1994 | G15: 1995 | H15: 1996 | I15: 1997 | J15: 1998 | K15: 1999 | L15: 2000 | M15: 2001 | N15: 2002 | O15: 2003 | P15: 2004 | Q15: 2005 | R15: 2006 | S15: 2007 | T15: 2008 | U15: 2009 | V15: 2010 | W15: 2011 | X15: 2012 | Y15: 2013 | Z15: 2014 | AA15: 2015 | AB15: 2016 | AC15: 2017 | AD15: 2018 | AE15: 2019 | AF15: 2020 | AG15: 2021 | AH15: 2022 | AI15: 2023
A16: France1 | B16: 57996401 | C16: 58280135 | D16: 58571237 | E16: 58852002 | F16: 59070077 | G16: 59280577 | H16: 59487413 | I16: 59691177 | J16: 59899347 | K16: 60122665 | L16: 60508150 | M16: 60941410 | N16: 61385070 | O16: 61824030 | P16: 62251062 | Q16: 62730537 | R16: 63186117 | S16: 63600690 | T16: 63961859 | U16: 64304500 | V16: 64612939 | W16: 64933400 | X16: 65241241 | Y16: 65564756 | Z16: 66130873 | AA16: 66422469 | AB16: 66602645 | AC16: 66774482 | AD16: 66992159 | AE16: 67257982 | AF16: 67441850 | AG16: 67635124 | AH16: 67842591 | AI16: 68042591
A17: France métropolitaine | B17: 56577000 | C17: 56 840 661 | D17: 57 110 533 | E17: 57 369 161 | F17: 57 565 008 | G17: 57 752 535 | H17: 57 935 959 | I17: 58 116 018 | J17: 58 298 962 | K17: 58 496 613 | L17: 58 858 198 | M17: 59 266 572 | N17: 59 685 899 | O17: 60 101 841 | P17: 60 505 421 | Q17: 60 963 264 | R17: 61 399 733 | S17: 61 795 238 | T17: 62 134 866 | U17: 62 465 709 | V17: 62 765 235 | W17: 63 070 344 | X17: 63 375 971 | Y17: 63 697 865 | Z17: 64 027 958 | AA17: 64 300 821 | AB17: 64 468 792 | AC17: 64 639 133 | AD17: 64 844 037 | AE17: 65 096 768 | AF17: 65 269 154 | AG17: 65 450 219 | AH17: 65 646 837 | AI17: 65 834 837
AG18: (p) | AH18: (p) | AI18: (p)
A19: p : données provisoires arrêtées à fin novembre 2022.
A20: 1. France hors Mayotte jusqu'en 2013 et y compris Mayotte à partir de 2014.
A21: Lecture : au 1er janvier 2023, la France compte 68 042 591 habitants.
A22: Champ : France.
A23: Source : Insee, estimations de population.
A26: https://www.insee.fr/fr/statistiques/serie/010548499#Telechargement
A27: idBank | B27: Dernière mise à jour | C27: Zone géographique | D27: Nature | E27: Prix de référence | F27: Produit | G27: Correction | H27: Opérations dans la comptabilité nationale | I27: Unité | J27: Puissance | K27: Indicateur | L27: Secteurs institutionnels | M27: Périodicité
A28: 010548499 | B28: 31/05/2023 08:57 | C28: France | D28: Valeur absolue | E28: Prix chaîné année de base (non équilibré) | F28: Ensemble des produits | G28: Non corrigé | H28: PIB - Produit intérieur brut | I28: euros de 2014 | J28: 6 | K28: PIB - Produit intérieur brut | L28: S0 - Ensemble des secteurs institutionnels | M28: Annuelle
A30: Année | B30: 1990 | C30: 1991 | D30: 1992 | E30: 1993 | F30: 1994 | G30: 1995 | H30: 1996 | I30: 1997 | J30: 1998 | K30: 1999 | L30: 2000 | M30: 2001 | N30: 2002 | O30: 2003 | P30: 2004 | Q30: 2005 | R30: 2006 | S30: 2007 | T30: 2008 | U30: 2009 | V30: 2010 | W30: 2011 | X30: 2012 | Y30: 2013 | Z30: 2014 | AA30: 2015 | AB30: 2016 | AC30: 2017 | AD30: 2018 | AE30: 2019 | AF30: 2020 | AG30: 2021 | AH30: 2022
A31: PIB | B31: 1480286 | C31: 1495802 | D31: 1519725 | E31: 1510171 | F31: 1545787 | G31: 1578351 | H31: 1600653 | I31: 1638049 | J31: 1696833 | K31: 1754888 | L31: 1823744 | M31: 1859922 | N31: 1881042 | O31: 1896526 | P31: 1950193 | Q31: 1982629 | R31: 2031190 | S31: 2080441 | T31: 2085745 | U31: 2025815 | V31: 2065307 | W31: 2110593 | X31: 2117202 | Y31: 2129404 | Z31: 2149765 | AA31: 2173690 | AB31: 2197502 | AC31: 2247856 | AD31: 2289780 | AE31: 2331980 | AF31: 2156138 | AG31: 2294890 | AH31: 2351224
A33: Q | B33: Couvert par le secret statistique
A34: E | B34: Estimation
A35: F | B35: Prévision
A36: P | B36: Provisoire
A37: SD | B37: Valeur semi-définitive
A38: R | B38: Révision
A39: A | B39: Valeur normale
A40: N | B40: Valeur non significative
A41: O | B41: Valeur manquante
A42: U | B42: Valeur atypique

Sheet Donnees_OECD
A1: =DotStatQuery(B1) -> #NAME? | B1: Désolé, la requête est trop grande pour la cellule Excel. Vous ne pourrez pas mettre à jour votre table avec .Stat Populator.
A2: https://stats.oecd.org/
A3: Ensemble de données : Ressources matérielles
A4: Variable | C4: Consommation intérieure de matières
A5: Groupe | C5: Total
A6: Unité
A7: Année | C7: 1970 | E7: 1980 | G7: 1990 | I7: 2000 | K7: 2005 | M7: 2010 | O7: 2015 | Q7: 2016 | S7: 2017 | U7: 2018 | W7: 2019 | Y7: 2020
A8: Pays
A9: Australie | D9: 513.9468 | F9: 646.3462 | H9: 758.4191 | J9: 873.3383 | L9: 880.2077 | N9: 805.4158 | P9: 862.1725 | R9: 825.1514 | T9: 955.4993 | V9: 970.4127 | X9: 1022.115 | Z9: ..
A10: Autriche | D10: .. | F10: .. | H10: .. | I10: (B) | J10: 161.467 | L10: 172.1871 | N10: 160.1272 | P10: 159.1252 | R10: 167.6855 | T10: 166.2848 | V10: 168.2883 | X10: 167.3412 | Y10: (E) | Z10: 165.8329
A11: Belgique | D11: .. | F11: .. | H11: 147.1828 | J11: 161.1036 | L11: 159.4728 | N11: 162.0833 | P11: 152.8959 | R11: 153.304 | T11: 157.7259 | V11: 153.6463 | X11: 158.6769 | Y11: (E) | Z11: 156.0952
A12: Canada | D12: 814.8855 | F12: 1142.255 | H12: 1266.392 | J12: 1468.01 | L12: 1557.481 | N12: 1796.09 | P12: 2039.979 | R12: 1995.551 | T12: 2109.678 | V12: 2074.958 | X12: 2134.25 | Z12: ..
A13: Chili | D13: 98.733 | F13: 137.8572 | H13: 212.7531 | J13: 665.597 | L13: 826.4566 | N13: 845.9492 | P13: 920.319 | R13: 930.2104 | T13: 929.6414 | V13: 980.9503 | X13: 1004.123 | Z13: ..
A14: Colombie | D14: 156.9353 | F14: 211.8762 | H14: 248.4154 | J14: 289.6134 | L14: 311.768 | N14: 325.9583 | P14: 392.6972 | R14: 380.6301 | T14: 339.9494 | V14: 360.9829 | X14: 383.1309 | Z14: ..
A15: Costa Rica | D15: 15.2901 | F15: 22.4246 | H15: 25.8457 | J15: 33.7955 | L15: 36.4083 | N15: 45.7731 | P15: 46.6548 | R15: 47.8234 | T15: 51.5763 | V15: 47.8442 | X15: 49.1677 | Z15: ..
A16: République tchèque | D16: .. | F16: .. | H16: .. | J16: 179.83 | L16: 187.7349 | N16: 167.629 | P16: 166.9133 | R16: 164.6916 | T16: 165.941 | V16: 168.6796 | X16: 169.8013 | Z16: 157.5301
A17: Danemark | D17: .. | F17: .. | H17: .. | J17: 137.3561 | L17: 151.7639 | N17: 118.0106 | P17: 130.5847 | R17: 135.4072 | T17: 140.2547 | V17: 140.5993 | X17: 142.6721 | Z17: 140.1065
A18: Estonie | D18: .. | F18: .. | H18: .. | J18: 21.7366 | L18: 30.5637 | N18: 32.1547 | P18: 34.3847 | R18: 33.9199 | T18: 40.2073 | V18: 41.9228 | X18: 37.6434 | Z18: 37.9054
A19: Finlande | D19: .. | F19: .. | H19: .. | I19: (E) | J19: 173.4322 | K19: (E) | L19: 191.0295 | M19: (E) | N19: 182.9768 | P19: 166.1961 | R19: 172.101 | T19: 180.7765 | V19: 189.7626 | X19: 173.3802 | Z19: 181.856
A20: France | D20: .. | F20: .. | H20: 825.9642 | J20: 880.9775 | L20: 851.9335 | N20: 778.1779 | P20: 734.4152 | R20: 718.094 | T20: 776.7061 | V20: 760.2894 | X20: 767.4615 | Y20: (E) | Z20: 691.1107
A21: Allemagne | D21: .. | F21: .. | H21: .. | J21: 1430.198 | L21: 1265.379 | N21: 1217.738 | P21: 1233.971 | R21: 1251.016 | T21: 1266.114 | V21: 1234.65 | X21: 1184.452 | Y21: (E) | Z21: 1106.079
A22: Grèce | D22: .. | F22: .. | H22: .. | I22: (E) | J22: 160.242 | K22: (E) | L22: 187.8237 | N22: 186.1739 | P22: 144.7639 | R22: 136.8354 | T22: 134.9127 | V22: 130.7554 | X22: 124.2336 | Y22: (E) | Z22: 99.4502
A23: Hongrie | D23: .. | F23: .. | H23: .. | J23: 117.5064 | L23: 179.3285 | N23: 98.1095 | P23: 125.262 | R23: 119.8436 | T23: 133.8934 | V23: 153.1623 | X23: 159.2554 | Y23: (E) | Z23: 139.851
A24: Islande | D24: 2.4441 | F24: 4.0801 | H24: 3.3834 | J24: 7.6075 | L24: 12.8885 | N24: 10.1965 | P24: 7.2573 | R24: 9.8313 | T24: 7.8825 | V24: 8.3746 | X24: 6.8082 | Z24: 5.1461
A25: Irlande | D25: .. | F25: .. | H25: .. | J25: 126.9019 | L25: 161.5973 | N25: 103.0895 | P25: 95.39 | R25: 102.3348 | T25: 109.2686 | V25: 116.989 | X25: 120.4314 | Z25: 110.5284
A26: Israël | D26: 24.0324 | F26: 73.1731 | H26: 109.0438 | J26: 91.406 | L26: 97.1865 | N26: 106.1571 | P26: 169.5724 | R26: 122.1284 | T26: 186.7267 | V26: 186.9446 | X26: 193.2642 | Z26: ..
A27: Italie | D27: .. | F27: .. | H27: .. | J27: 758.0406 | L27: 834.8472 | N27: 687.2592 | P27: 486.4537 | R27: 487.8522 | T27: 485.3237 | V27: 490.911 | X27: 502.7502 | Y27: (E) | Z27: 462.9595
A28: Japon | D28: 954.961 | F28: 1508.279 | H28: 1735.694 | J28: 1684.768 | L28: 1581.349 | N28: 1399.048 | P28: 1430.956 | R28: 1414.117 | T28: 1404.321 | V28: 1383.676 | X28: 1388.858 | Z28: ..
A29: Corée | D29: 113.0893 | F29: 207.4007 | H29: 487.2292 | J29: 787.1839 | L29: 793.8519 | N29: 842.6307 | P29: 963.9407 | R29: 1006.805 | T29: 1036.168 | V29: 1031.185 | X29: 1020.561 | Z29: ..
A30: Lettonie | D30: .. | F30: .. | H30: .. | J30: 15.1835 | L30: 25.1145 | N30: 20.2589 | P30: 25.6281 | R30: 22.8706 | T30: 25.9833 | V30: 28.1794 | X30: 28.3237 | Z30: 28.231
A31: Lituanie | D31: .. | F31: .. | H31: .. | J31: 28.9414 | L31: 40.6912 | N31: 38.6985 | P31: 44.3442 | R31: 45.9376 | T31: 51.4553 | V31: 50.6535 | X31: 54.0927 | Z31: 57.0595
A32: Luxembourg | D32: .. | F32: .. | H32: .. | J32: 11.4846 | L32: 11.8106 | N32: 11.3009 | P32: 13.4251 | R32: 13.5702 | T32: 14.3468 | V32: 13.3795 | X32: 13.7827 | Z32: 13.2018
A33: Mexique | D33: 382.0732 | F33: 602.8181 | H33: 768.2428 | J33: 964.7531 | L33: 1095.29 | N33: 1133.297 | P33: 1333.085 | R33: 1385.738 | T33: 1341.382 | V33: 1403.94 | X33: 1423.942 | Z33: ..
A34: Pays-Bas | D34: .. | F34: .. | H34: .. | J34: 200.5957 | L34: 182.8348 | N34: 191.9641 | P34: 187.0993 | R34: 168.5607 | T34: 155.8931 | V34: 160.5319 | W34: (E) | X34: 149.9051 | Y34: (E) | Z34: 139.4292
A35: Nouvelle-Zélande | D35: 132.1367 | F35: 127.082 | H35: 123.6188 | J35: 141.8282 | L35: 153.8728 | N35: 138.0685 | P35: 148.3906 | R35: 147.5597 | T35: 145.4013 | V35: 147.7135 | X35: 147.1992 | Z35: ..
A36: Norvège | D36: .. | F36: .. | H36: .. | J36: .. | L36: .. | N36: 129.3235 | P36: 158.3042 | R36: 130.7983 | T36: 129.6322 | V36: 142.7574 | X36: 167.1365 | Z36: ..
A37: Pologne | D37: .. | F37: .. | H37: .. | J37: 523.0052 | L37: 531.226 | N37: 622.6881 | P37: 623.443 | R37: 643.618 | T37: 682.692 | V37: 708.7708 | X37: 676.8652 | Z37: 650.1213
A38: Portugal | D38: .. | F38: .. | H38: .. | J38: 201.5252 | L38: 195.404 | N38: 201.8539 | P38: 159.4193 | R38: 152.5739 | T38: 167.1757 | V38: 166.1943 | X38: 167.99 | Z38: 165.1506
A39: République slovaque | D39: .. | F39: .. | H39: .. | J39: 54.3625 | L39: 74.5363 | N39: 71.2525 | P39: 67.013 | R39: 66.1872 | T39: 68.3856 | V39: 72.3807 | X39: 65.7425 | Z39: 63.5344
A40: Slovénie | D40: .. | F40: .. | H40: .. | J40: 34.3273 | L40: 37.0691 | N40: 32.9795 | P40: 27.7196 | R40: 26.7918 | T40: 27.3627 | V40: 30.068 | X40: 28.49 | Z40: 27.7079
...

Sheet Graph 1
A1: Graphique 1 : extraction intérieure, importations et exportations de matières de la France
A3: Consommation intérieure apparente de matière (Direct Material Consumption)
A4: En millions de tonnes
A6: tableau automatisé | B6: 1990 // | C6: // 2000 // | D6: // 2007 | E6: 2008 | F6: 2009 | G6: 2010 | H6: 2011 | I6: 2012 | J6: 2013 | K6: 2014 | L6: 2015 | M6: 2016 | N6: 2017 | O6: 2018 | P6: 2019 | Q6: 2020 | R6: 2021
A7: Extraction intérieure | B7: =Donnees_Eurostat_MFA!C17/1000 -> 709.0348 | C7: =Donnees_Eurostat_MFA!M17/1000 -> 735.0109 | D7: =Donnees_Eurostat_MFA!T17/1000 -> 737.20861 | E7: =Donnees_Eurostat_MFA!U17/1000 -> 719.40748 | F7: =Donnees_Eurostat_MFA!V17/1000 -> 659.05465 | G7: =Donnees_Eurostat_MFA!W17/1000 -> 636.40428 | H7: =Donnees_Eurostat_MFA!X17/1000 -> 654.97222 | I7: =Donnees_Eurostat_MFA!Y17/1000 -> 634.4475 | J7: =Donnees_Eurostat_MFA!Z17/1000 -> 636.33151 | K7: =Donnees_Eurostat_MFA!AA17/1000 -> 639.68209 | ... R7: =Donnees_Eurostat_MFA!AH17/1000 -> 649.62365
A8: Importation apparente (matériaux et produits) | B8: 286.2 | C8: =Donnees_Eurostat_MFA!M93/1000 -> 347.21648 | D8: =Donnees_Eurostat_MFA!T93/1000 -> 366.17713 | E8: =Donnees_Eurostat_MFA!U93/1000 -> 370.13835 | F8: =Donnees_Eurostat_MFA!V93/1000 -> 302.33648 | G8: =Donnees_Eurostat_MFA!W93/1000 -> 331.94322 | H8: =Donnees_Eurostat_MFA!X93/1000 -> 382.34296 | I8: =Donnees_Eurostat_MFA!Y93/1000 -> 373.12537 | J8: =Donnees_Eurostat_MFA!Z93/1000 -> 373.08802 | K8: =Donnees_Eurostat_MFA!AA93/1000 -> 366.29156 | ... R8: =Donnees_Eurostat_MFA!AH93/1000 -> 355.37975
A9: Exportation apparente (matériaux et produits) | B9: -163.7 | C9: =-Donnees_Eurostat_MFA!M169/1000 -> -197.70991 | D9: =-Donnees_Eurostat_MFA!T169/1000 -> -191.56341 | E9: =-Donnees_Eurostat_MFA!U169/1000 -> -195.37839 | F9: =-Donnees_Eurostat_MFA!V169/1000 -> -161.33568 | G9: =-Donnees_Eurostat_MFA!W169/1000 -> -183.67945 | H9: =-Donnees_Eurostat_MFA!X169/1000 -> -230.89951 | I9: =-Donnees_Eurostat_MFA!Y169/1000 -> -219.79562 | J9: =-Donnees_Eurostat_MFA!Z169/1000 -> -219.59628 | K9: =-Donnees_Eurostat_MFA!AA169/1000 -> -224.64347 | ... R9: =-Donnees_Eurostat_MFA!AH169/1000 -> -212.66699
A10: Total (consommation intérieure de matières, DMC) | B10: =B7+B8+B9 -> 831.5348 | C10: =C7+C8+C9 -> 884.51747 | D10: =D7+D8+D9 -> 911.82233 | E10: =E7+E8+E9 -> 894.16745 | F10: =F7+F8+F9 -> 800.05545 | G10: =G7+G8+G9 -> 784.66804 | H10: =H7+H8+H9 -> 806.41567 | I10: =I7+I8+I9 -> 787.77724 | ... R10: =R7+R8+R9 -> 792.33641
A12: Note : les exportations sont indiquées en valeurs négatives, de telle sorte que le besoin apparent en matières
A13: de l'économie est donné par la somme des valeurs positives (extraction intérieure + importations).
A14: Source : Agreste - Douanes françaises - Insee. Traitements : SDES, 2023
A16: Graphique 1 : extraction intérieure, importations et exportations de matières de la France par type de matériaux
A17: En %
A18: 2021
A19: tableau automatisé | B19: Total (consommation intérieure de matières, DMC) | C19: Extraction intérieure | D19: Importation apparente (matériaux et produits) | E19: Exportation apparente (matériaux et produits)
A20: Biomasse : produits issus de l'agriculture et de la pêche | B20: =C20+D20-E20 -> 208.5775 | C20: =(Donnees_Eurostat_MFA!AH18-Donnees_Eurostat_MFA!AH37)/1000 -> 231.63235 | D20: =(Donnees_Eurostat_MFA!AH94-Donnees_Eurostat_MFA!AH113)/1000 -> 54.848001 | E20: =(Donnees_Eurostat_MFA!AH170-Donnees_Eurostat_MFA!AH189)/1000 -> 77.902846
A21: Bois et produits dérivés | B21: =C21+D21-E21 -> 22.981122 | C21: =Donnees_Eurostat_MFA!AH37/1000 -> 22.525 | D21: =Donnees_Eurostat_MFA!AH113/1000 -> 8.831653 | E21: =Donnees_Eurostat_MFA!AH189/1000 -> 8.375531
A22: Minerais métalliques et produits à base dominante de métal | B22: =C22+D22-E22 -> 17.667725 | C22: =Donnees_Eurostat_MFA!AH50/1000 -> 0.236508 | D22: =Donnees_Eurostat_MFA!AH126/1000 -> 61.683614 | E22: =Donnees_Eurostat_MFA!AH202/1000 -> 44.252397
A23: Minéraux non métalliques et produits à dominante non métallique | B23: =C23+D23-E23 -> 420.3164 | C23: =Donnees_Eurostat_MFA!AH63/1000 -> 394.53952 | D23: =Donnees_Eurostat_MFA!AH139/1000 -> 51.666317 | E23: =Donnees_Eurostat_MFA!AH215/1000 -> 25.889436
A24: Charbons et produits dérivés | B24: =C24+D24-E24 -> 8.169841 | C24: =Donnees_Eurostat_MFA!AH75/1000 -> 0 | D24: =Donnees_Eurostat_MFA!AH151/1000 -> 8.721093 | E24: =Donnees_Eurostat_MFA!AH227/1000 -> 0.551252
A25: Pétrole (dont pétrole raffiné) | B25: =C25+D25-E25 -> 79.491235 | C25: =Donnees_Eurostat_MFA!AH81/1000 -> 0.672466 | D25: =Donnees_Eurostat_MFA!AH157/1000 -> 92.758416 | E25: =Donnees_Eurostat_MFA!AH233/1000 -> 13.939647
A26: Gaz naturels et produits dérivés | B26: =C26+D26-E26 -> 22.879666 | C26: =Donnees_Eurostat_MFA!AH82/1000 -> 0.017814 | D26: =Donnees_Eurostat_MFA!AH158/1000 -> 26.931561 | E26: =Donnees_Eurostat_MFA!AH234/1000 -> 4.069709
A27: Produits à base dominante de combustibles fossiles | B27: =C27+D27-E27 -> 4.438511 | C27: =(Donnees_Eurostat_MFA!AH74/1000-SUM('Graph 1'!C24:C26)) -> 0 | D27: =Donnees_Eurostat_MFA!AH150/1000-SUM('Graph 1'!D24:D26) -> 22.845052 | E27: =Donnees_Eurostat_MFA!AH226/1000 - SUM('Graph 1'!E24:E26) -> 18.406541
A28: Autres produits | B28: =C28+D28-E28 -> 7.81441 | C28: =Donnees_Eurostat_MFA!AH17/1000-SUM('Graph 1'!C20:C27) -> 0 | D28: =Donnees_Eurostat_MFA!AH93/1000-SUM('Graph 1'!D20:D27) -> 27.094043 | E28: =Donnees_Eurostat_MFA!AH169/1000 - SUM('Graph 1'!E20:E27) -> 19.279633
A29: Total | B29: =C29+D29-E29 -> 792.33641 | C29: =Donnees_Eurostat_MFA!AH17/1000 -> 649.62365 | D29: =Donnees_Eurostat_MFA!AH93/1000 -> 355.37975 | E29: =Donnees_Eurostat_MFA!AH169/1000 -> 212.66699
A30: Sources : Agreste ; Douanes françaises ; Insee. Traitements : SDES, 2023
A54: tableau automatisé | B54: Total (consommation intérieure de matières, DMC) | C54: Extraction intérieure | D54: Importation apparente (matériaux et produits) | E54: Exportation apparente (matériaux et produits)
A55: Biomasse : produits issus de l'agriculture et de la pêche | B55: =B20/B$29 *100 -> 26.324361 | C55: =C20/C$29 *100 -> 35.65639 | D55: =D20/D$29 *100 -> 15.433631 | E55: =E20/E$29 *100 -> 36.631376
A56: Bois et produits dérivés | B56: =B21/B$29 *100 -> 2.9004248 | C56: =C21/C$29 *100 -> 3.4673922 | D56: =D21/D$29 *100 -> 2.4851312 | E56: =E21/E$29 *100 -> 3.9383314
A57: Minerais métalliques et produits à base dominante de métal | B57: =B22/B$29 *100 -> 2.2298262 | C57: =C22/C$29 *100 -> 0.036406926 | D57: =D22/D$29 *100 -> 17.357099 | E57: =E22/E$29 *100 -> 20.808305
A58: Minéraux non métalliques et produits à dominante non métallique | B58: =B23/B$29 *100 -> 53.04772 | C58: =C23/C$29 *100 -> 60.733552 | D58: =D23/D$29 *100 -> 14.53834 | E58: =E23/E$29 *100 -> 12.173697
A59: Charbons et produits dérivés | B59: =B24/B$29 *100 -> 1.0311076 | C59: =C24/C$29 *100 -> 0 | D59: =D24/D$29 *100 -> 2.4540208 | E59: =E24/E$29 *100 -> 0.25920901
A60: Pétrole (dont pétrole raffiné) | B60: =B25/B$29 *100 -> 10.032511 | C60: =C25/C$29 *100 -> 0.10351624 | D60: =D25/D$29 *100 -> 26.10121 | E60: =E25/E$29 *100 -> 6.5546829
A61: Gaz naturels et produits dérivés | B61: =B26/B$29 *100 -> 2.8876202 | C61: =C26/C$29 *100 -> 0.0027422031 | D61: =D26/D$29 *100 -> 7.5782486 | E61: =E26/E$29 *100 -> 1.9136533
A62: Produits à base dominante de combustibles fossiles | B62: =B27/B$29 *100 -> 0.56018011 | C62: =C27/C$29 *100 -> 0 | D62: =D27/D$29 *100 -> 6.4283494 | E62: =E27/E$29 *100 -> 8.6551001
A63: Autres produits | B63: =B28/B$29 *100 -> 0.98624901 | C63: =C28/C$29 *100 -> 0 | D63: =D28/D$29 *100 -> 7.6239693 | E63: =E28/E$29 *100 -> 9.0656443
A64: Total | B64: =SUM(B55:B63) -> 100 | C64: =SUM(C55:C63) -> 100 | D64: =SUM(D55:D63) -> 100 | E64: =SUM(E55:E63) -> 100

Sheet Graph 2
A1: Graphique 2 : PIB et Consommation intérieure apparente de matières (DMC)
A4: tableau automatisé | B4: 1990 | C4: =B4+1 -> 1991 | D4: =C4+1 -> 1992 | E4: =D4+1 -> 1993 | F4: =E4+1 -> 1994 | G4: =F4+1 -> 1995 | H4: =G4+1 -> 1996 | I4: =H4+1 -> 1997 | J4: =I4+1 -> 1998 | ... U4: =T4+1 -> 2009 | V4: 2010 | W4: 2011 | X4: 2012 | Y4: 2013 | Z4: 2014 | AA4: 2015 | AB4: 2016 | AC4: 2017 | AD4: 2018 | AE4: 2019 | AF4: 2020 | AG4: 2021 | AH4: 2022 | AI4: Estimation Eurostat
A5: Biomasse | B5: =(Donnees_Eurostat_MFA!C18+Donnees_Eurostat_MFA!C94-Donnees_Eurostat_MFA!C170)/1000 -> 204.14547 | C5: =(Donnees_Eurostat_MFA!D18+Donnees_Eurostat_MFA!D94-Donnees_Eurostat_MFA!D170)/1000 -> 214.02076 | D5: =(Donnees_Eurostat_MFA!E18+Donnees_Eurostat_MFA!E94-Donnees_Eurostat_MFA!E170)/1000 -> 234.0908 | E5: =(Donnees_Eurostat_MFA!F18+Donnees_Eurostat_MFA!F94-Donnees_Eurostat_MFA!F170)/1000 -> 220.81991 | F5: =(Donnees_Eurostat_MFA!G18+Donnees_Eurostat_MFA!G94-Donnees_Eurostat_MFA!G170)/1000 -> 226.26891 | G5: =(Donnees_Eurostat_MFA!H18+Donnees_Eurostat_MFA!H94-Donnees_Eurostat_MFA!H170)/1000 -> 216.84326 | H5: =(Donnees_Eurostat_MFA!I18+Donnees_Eurostat_MFA!I94-Donnees_Eurostat_MFA!I170)/1000 -> 220.47428 | I5: =(Donnees_Eurostat_MFA!J18+Donnees_Eurostat_MFA!J94-Donnees_Eurostat_MFA!J170)/1000 -> 230.4995 | ... AH5: =(Donnees_Eurostat_MFA!AI18+Donnees_Eurostat_MFA!AI94-Donnees_Eurostat_MFA!AI170)/1000 -> 198.5842
A6: Minerais métalliques et produits principalement métalliques | B6: =(Donnees_Eurostat_MFA!C50+Donnees_Eurostat_MFA!C126-Donnees_Eurostat_MFA!C202)/1000 -> 29.647839 | C6: =(Donnees_Eurostat_MFA!D50+Donnees_Eurostat_MFA!D126-Donnees_Eurostat_MFA!D202)/1000 -> 25.609868 | D6: =(Donnees_Eurostat_MFA!E50+Donnees_Eurostat_MFA!E126-Donnees_Eurostat_MFA!E202)/1000 -> 22.593807 | E6: =(Donnees_Eurostat_MFA!F50+Donnees_Eurostat_MFA!F126-Donnees_Eurostat_MFA!F202)/1000 -> 15.465531 | F6: =(Donnees_Eurostat_MFA!G50+Donnees_Eurostat_MFA!G126-Donnees_Eurostat_MFA!G202)/1000 -> 20.372265 | G6: =(Donnees_Eurostat_MFA!H50+Donnees_Eurostat_MFA!H126-Donnees_Eurostat_MFA!H202)/1000 -> 22.787321 | H6: =(Donnees_Eurostat_MFA!I50+Donnees_Eurostat_MFA!I126-Donnees_Eurostat_MFA!I202)/1000 -> 18.03655 | I6: =(Donnees_Eurostat_MFA!J50+Donnees_Eurostat_MFA!J126-Donnees_Eurostat_MFA!J202)/1000 -> 18.824104 | ... AH6: =(Donnees_Eurostat_MFA!AI50+Donnees_Eurostat_MFA!AI126-Donnees_Eurostat_MFA!AI202)/1000 -> 16.183667
A7: Minéraux non métalliques | B7: =(Donnees_Eurostat_MFA!C63+Donnees_Eurostat_MFA!C139-Donnees_Eurostat_MFA!C215)/1000 -> 446.31248 | C7: =(Donnees_Eurostat_MFA!D63+Donnees_Eurostat_MFA!D139-Donnees_Eurostat_MFA!D215)/1000 -> 452.32088 | D7: =(Donnees_Eurostat_MFA!E63+Donnees_Eurostat_MFA!E139-Donnees_Eurostat_MFA!E215)/1000 -> 419.74144 | E7: =(Donnees_Eurostat_MFA!F63+Donnees_Eurostat_MFA!F139-Donnees_Eurostat_MFA!F215)/1000 -> 390.50295 | F7: =(Donnees_Eurostat_MFA!G63+Donnees_Eurostat_MFA!G139-Donnees_Eurostat_MFA!G215)/1000 -> 417.19829 | G7: =(Donnees_Eurostat_MFA!H63+Donnees_Eurostat_MFA!H139-Donnees_Eurostat_MFA!H215)/1000 -> 416.75827 | H7: =(Donnees_Eurostat_MFA!I63+Donnees_Eurostat_MFA!I139-Donnees_Eurostat_MFA!I215)/1000 -> 388.02387 | I7: =(Donnees_Eurostat_MFA!J63+Donnees_Eurostat_MFA!J139-Donnees_Eurostat_MFA!J215)/1000 -> 398.25219 | ... AH7: =(Donnees_Eurostat_MFA!AI63+Donnees_Eurostat_MFA!AI139-Donnees_Eurostat_MFA!AI215)/1000 -> 422.52352
A8: Combustibles fossiles (charbon, pétrole, gaz naturel) | B8: =(Donnees_Eurostat_MFA!C74+Donnees_Eurostat_MFA!C150-Donnees_Eurostat_MFA!C226)/1000 -> 146.2409 | C8: =(Donnees_Eurostat_MFA!D74+Donnees_Eurostat_MFA!D150-Donnees_Eurostat_MFA!D226)/1000 -> 153.26176 | D8: =(Donnees_Eurostat_MFA!E74+Donnees_Eurostat_MFA!E150-Donnees_Eurostat_MFA!E226)/1000 -> 153.14851 | E8: =(Donnees_Eurostat_MFA!F74+Donnees_Eurostat_MFA!F150-Donnees_Eurostat_MFA!F226)/1000 -> 138.83906 | F8: =(Donnees_Eurostat_MFA!G74+Donnees_Eurostat_MFA!G150-Donnees_Eurostat_MFA!G226)/1000 -> 139.55417 | G8: =(Donnees_Eurostat_MFA!H74+Donnees_Eurostat_MFA!H150-Donnees_Eurostat_MFA!H226)/1000 -> 139.6293 | H8: =(Donnees_Eurostat_MFA!I74+Donnees_Eurostat_MFA!I150-Donnees_Eurostat_MFA!I226)/1000 -> 148.49384 | I8: =(Donnees_Eurostat_MFA!J74+Donnees_Eurostat_MFA!J150-Donnees_Eurostat_MFA!J226)/1000 -> 143.60159 | ... AH8: =(Donnees_Eurostat_MFA!AI74+Donnees_Eurostat_MFA!AI150-Donnees_Eurostat_MFA!AI226)/1000 -> 115.68317
A9: PIB | B9: =Donnees_INSEE!B31/1000 -> 1480.286 | C9: =Donnees_INSEE!C31/1000 -> 1495.802 | D9: =Donnees_INSEE!D31/1000 -> 1519.725 | E9: =Donnees_INSEE!E31/1000 -> 1510.171 | F9: =Donnees_INSEE!F31/1000 -> 1545.787 | G9: =Donnees_INSEE!G31/1000 -> 1578.351 | H9: =Donnees_INSEE!H31/1000 -> 1600.653 | I9: =Donnees_INSEE!I31/1000 -> 1638.049 | ... AH9: =Donnees_INSEE!AH31/1000 -> 2351.224
A10: Consommation intérieure Totale (DMC), (Mt) | B10: =Donnees_Eurostat_MFA!C245/1000 -> 831.5172 | C10: =Donnees_Eurostat_MFA!D245/1000 -> 849.96848 | D10: =Donnees_Eurostat_MFA!E245/1000 -> 833.57592 | E10: =Donnees_Eurostat_MFA!F245/1000 -> 768.04408 | F10: =Donnees_Eurostat_MFA!G245/1000 -> 806.71337 | G10: =Donnees_Eurostat_MFA!H245/1000 -> 799.48137 | H10: =Donnees_Eurostat_MFA!I245/1000 -> 777.11494 | I10: =Donnees_Eurostat_MFA!J245/1000 -> 793.47315 | ... AG10: =Donnees_Eurostat_MFA!AH245/1000 -> 792.33641
A12: tableau automatisé | B12: 1990 | C12: =B12+1 -> 1991 | D12: =C12+1 -> 1992 | E12: =D12+1 -> 1993 | F12: =E12+1 -> 1994 | G12: =F12+1 -> 1995 | H12: =G12+1 -> 1996 | I12: =H12+1 -> 1997 | J12: =I12+1 -> 1998 | ... U12: =T12+1 -> 2009 | V12: 2010 | W12: 2011 | X12: 2012 | Y12: 2013 | Z12: 2014 | AA12: 2015 | AB12: 2016 | AC12: 2017 | AD12: 2018 | AE12: 2019 | AF12: 2020 | AG12: 2021 | AH12: 2022 | AI12: Estimation Eurostat
A13: Biomasse | B13: 100 | C13: =C5/$B5*100 -> 104.83738 | D13: =D5/$B5*100 -> 114.66862 | E13: =E5/$B5*100 -> 108.16792 | F13: =F5/$B5*100 -> 110.8371 | G13: =G5/$B5*100 -> 106.21997 | H13: =H5/$B5*100 -> 107.99862 | I13: =I5/$B5*100 -> 112.90944 | J13: =J5/$B5*100 -> 115.39345 | ... AH13: =AH5/$B5*100 -> 97.27583
A14: Minerais métalliques et produits principalement métalliques | B14: 100 | C14: =C6/$B6*100 -> 86.380218 | D14: =D6/$B6*100 -> 76.207264 | E14: =E6/$B6*100 -> 52.164109 | F14: =F6/$B6*100 -> 68.714165 | G14: =G6/$B6*100 -> 76.859973 | H14: =H6/$B6*100 -> 60.835969 | I14: =I6/$B6*100 -> 63.492331 | J14: =J6/$B6*100 -> 70.828532 | ... AH14: =AH6/$B6*100 -> 54.586329
A15: Minéraux non métalliques | B15: 100 | C15: =C7/$B7*100 -> 101.34623 | D15: =D7/$B7*100 -> 94.046538 | E15: =E7/$B7*100 -> 87.495415 | F15: =F7/$B7*100 -> 93.476725 | G15: =G7/$B7*100 -> 93.378135 | H15: =H7/$B7*100 -> 86.939956 | I15: =I7/$B7*100 -> 89.231694 | J15: =J7/$B7*100 -> 92.391242 | ... AH15: =AH7/$B7*100 -> 94.669886
A16: Combustibles fossiles (charbon, pétrole, gaz naturel) | B16: 100 | C16: =C8/$B8*100 -> 104.80089 | D16: =D8/$B8*100 -> 104.72345 | E16: =E8/$B8*100 -> 94.938599 | F16: =F8/$B8*100 -> 95.427596 | G16: =G8/$B8*100 -> 95.478967 | H16: =H8/$B8*100 -> 101.54057 | I16: =I8/$B8*100 -> 98.195235 | J16: =J8/$B8*100 -> 99.841505 | ... AH16: =AH8/$B8*100 -> 79.104523
A17: PIB | B17: 100 | C17: =C9/$B9*100 -> 101.04818 | D17: =D9/$B9*100 -> 102.66428 | E17: =E9/$B9*100 -> 102.01887 | F17: =F9/$B9*100 -> 104.42489 | G17: =G9/$B9*100 -> 106.62473 | H17: =H9/$B9*100 -> 108.13133 | I17: =I9/$B9*100 -> 110.6576 | J17: =J9/$B9*100 -> 114.62873 | ... AH17: =AH9/$B9*100 -> 158.83579
A18: DMC | B18: 100 | C18: =C10/$B10*100 -> 102.21899 | D18: =D10/$B10*100 -> 100.24759 | E18: =E10/$B10*100 -> 92.36659 | F18: =F10/$B10*100 -> 97.017039 | G18: =G10/$B10*100 -> 96.147303 | H18: =H10/$B10*100 -> 93.45747 | I18: =I10/$B10*100 -> 95.424742 | J18: =J10/$B10*100 -> 98.36291 | ... AH18: =AH10/$B10*100 -> 0
A19: Source : Agreste, Douanes françaises, Insee, SDES . Traitements : SDES 2023
A20: Note : La consommation intérieure apparente de matières (DMC, Domestic Material Consumption) agrège, en tonnes, les combustibles fossiles, les produits minéraux et agricoles, extraits du territoire national (métropole et Dom) ou importés sous forme de matières premières ou de produits finis, moins les exportations. N.B. Elle ne prend pas en compte les flux dits « cachés » : ces derniers correspondent d’une part à des quantités de matières extraites qui ne sont pas utilisées (excavation de terres dans les activités extractives ou de construction, érosion des sols liée à l’agriculture). D’autre part, dans le cas des importations/exportations, les flux cachés incluent également des flux indirects associés (utilisation de combustibles ou d’autres produits qui ne franchissent pas la frontière avec les matériaux/produits concernés). L’estimation des flux cachés est réalisée sur la base de coefficients internationaux.
A21: Définition
A22: DMC (consommation intérieure apparente de matières au sens de la comptabilité de flux de matières – règlement 691/2011 CE) : évalue en terme physiques la quantité de matières consommées par la population d’un territoire.
A23: Productivité matières = PIB/DMC (en €/kg)
A25: Note : PIB en volume, prix chaînés, base 2014.
A26: Sources : Agreste/SSP ; Douanes françaises ; Insee. Traitements : SDES 2023
A28: Graphique 2 : PIB et consommation intérieure apparente de matières (DMC)
A29: En indice base 100 en 1990
A53: Note : PIB en volume, prix chaînés, base 2014.
A54: Sources : Agreste/SSP ; Douanes françaises ; Insee. Traitements : SDES, 2023

Sheet Graph 3
A1: Graphique 3 : Evolution de la consommation et de la productivité matières de l’économie française
A4: tableau automatisé | B4: 1990 | C4: 1991 | D4: 1992 | E4: 1993 | F4: 1994 | G4: 1995 | H4: 1996 | I4: 1997 | J4: 1998 | K4: 1999 | L4: 2000 | M4: 2001 | N4: 2002 | O4: 2003 | P4: 2004 | Q4: 2005 | R4: 2006 | S4: 2007 | T4: 2008 | U4: 2009 | V4: 2010 | W4: 2011 | X4: 2012 | Y4: 2013 | Z4: 2014 | AA4: 2015 | AB4: 2016 | AC4: 2017 | AD4: 2018 | AE4: 2019 | AF4: 2020 | AG4: 2021 | AH4: 2022
A5: PIB (milliards d'euros, prix chaînés, base 2014) | B5: =Donnees_INSEE!B31/1000 -> 1480.286 | C5: =Donnees_INSEE!C31/1000 -> 1495.802 | D5: =Donnees_INSEE!D31/1000 -> 1519.725 | E5: =Donnees_INSEE!E31/1000 -> 1510.171 | F5: =Donnees_INSEE!F31/1000 -> 1545.787 | G5: =Donnees_INSEE!G31/1000 -> 1578.351 | H5: =Donnees_INSEE!H31/1000 -> 1600.653 | I5: =Donnees_INSEE!I31/1000 -> 1638.049 | ... AH5: =Donnees_INSEE!AH31/1000 -> 2351.224
A6: Consommation intérieure de matières (DMC, Mt)* | B6: ='Graph 2'!B10 -> 831.5172 | C6: ='Graph 2'!C10 -> 849.96848 | D6: ='Graph 2'!D10 -> 833.57592 | E6: ='Graph 2'!E10 -> 768.04408 | F6: ='Graph 2'!F10 -> 806.71337 | G6: ='Graph 2'!G10 -> 799.48137 | H6: ='Graph 2'!H10 -> 777.11494 | I6: ='Graph 2'!I10 -> 793.47315 | ... AH6: ='Graph 2'!AH10 -> 0
A7: Consommation intérieure de matières par personne (DMC/population, t/habitant)* | B7: =B6/B9*1000 -> 14.337393 | C7: =C6/C9*1000 -> 14.584189 | D7: =D6/D9*1000 -> 14.231831 | E7: =E6/E9*1000 -> 13.050433 | F7: =F6/F9*1000 -> 13.656887 | G7: =G6/G9*1000 -> 13.486397 | H7: =H6/H9*1000 -> 13.063519 | I7: =I6/I9*1000 -> 13.292972 | ... AH7: =AH6/AH9*1000 -> 0
A8: Productivité matières (PIB/DMC, en €/kg)** | B8: =B5/B6 -> 1.7802229 | C8: =C5/C6 -> 1.7598323 | D8: =D5/D6 -> 1.8231393 | E8: =E5/E6 -> 1.9662556 | F8: =F5/F6 -> 1.9161539 | G8: =G5/G6 -> 1.9742186 | H8: =H5/H6 -> 2.0597378 | I8: =I5/I6 -> 2.0644038 | ... AG8: =AG5/AG6 -> 2.8963581 | AH8: -
A9: Population | B9: =Donnees_INSEE!B16/1000 -> 57996.401 | C9: =Donnees_INSEE!C16/1000 -> 58280.135 | D9: =Donnees_INSEE!D16/1000 -> 58571.237 | E9: =Donnees_INSEE!E16/1000 -> 58852.002 | F9: =Donnees_INSEE!F16/1000 -> 59070.077 | G9: =Donnees_INSEE!G16/1000 -> 59280.577 | H9: =Donnees_INSEE!H16/1000 -> 59487.413 | I9: =Donnees_INSEE!I16/1000 -> 59691.177 | ... AH9: =Donnees_INSEE!AH16/1000 -> 67842.591
A10: Sources : Agreste ; douanes françaises ; Insee ; SDES ; SSP ; Unicem. Traitements : SDES, 2023
A12: tableau automatisé | B12: 1990 | C12: =B12+1 -> 1991 | D12: =C12+1 -> 1992 | E12: =D12+1 -> 1993 | F12: =E12+1 -> 1994 | G12: =F12+1 -> 1995 | H12: =G12+1 -> 1996 | I12: =H12+1 -> 1997 | J12: =I12+1 -> 1998 | ... AC12: =AB12+1 -> 2017 | AD12: 2018 | AE12: 2019 | AF12: 2020 | AG12: 2021 | AH12: 2022
A13: =A6 -> Consommation intérieure de matières (DMC, Mt)* | B13: 100 | C13: =C6/$B6*100 -> 102.21899 | D13: =D6/$B6*100 -> 100.24759 | E13: =E6/$B6*100 -> 92.36659 | F13: =F6/$B6*100 -> 97.017039 | G13: =G6/$B6*100 -> 96.147303 | H13: =H6/$B6*100 -> 93.45747 | I13: =I6/$B6*100 -> 95.424742 | J13: =J6/$B6*100 -> 98.36291 | ... AH13: =AH6/$B6*100 -> 0
A14: =A7 -> Consommation intérieure de matières par personne (DMC/population, t/habitant)* | B14: 100 | C14: =C7/$B7*100 -> 101.72134 | D14: =D7/$B7*100 -> 99.263725 | E14: =E7/$B7*100 -> 91.023748 | F14: =F7/$B7*100 -> 95.253627 | G14: =G7/$B7*100 -> 94.064495 | H14: =H7/$B7*100 -> 91.115021 | I14: =I7/$B7*100 -> 92.715404 | J14: =J7/$B7*100 -> 95.238013 | ... AH14: =AH7/$B7*100 -> 0
A15: =A8 -> Productivité matières (PIB/DMC, en €/kg)** | B15: 100 | C15: =C8/$B8*100 -> 98.854602 | D15: =D8/$B8*100 -> 102.41073 | E15: =E8/$B8*100 -> 110.44997 | F15: =F8/$B8*100 -> 107.63562 | G15: =G8/$B8*100 -> 110.89727 | H15: =H8/$B8*100 -> 115.70111 | I15: =I8/$B8*100 -> 115.96322 | J15: =J8/$B8*100 -> 116.53653 | ... AG15: =AG8/$B8*100 -> 162.69637
A16: * PIB/DMC en volume (prix constants) base 2014
A17: Note : La consommation intérieure apparente de matières agrège, en tonnes, les combustibles fossiles, les produits minéraux et agricoles, extraits du territoire national (métropole et Dom) ou importés sous forme de matières premières ou de produits finis, moins les exportations. N.B. Elle ne prend pas en compte les flux dits « cachés » : ces derniers correspondent d’une part à des quantités de matières extraites qui ne sont pas utilisées (excavation de terres dans les activités extractives ou de construction, érosion des sols liée à l’agriculture). D’autre part, dans le cas des importations/exportations, les flux cachés incluent également des flux indirects associés (utilisation de combustibles ou d’autres produits qui ne franchissent pas la frontière avec les matériaux/produits concernés). L’estimation des flux cachés est réalisée sur la base de coefficients internationaux ; le SDES a engagé des travaux pour affiner ces coefficients et les adapter au cas de la France.
A18: Sources : Agreste/SSP ; douanes françaises ; Insee. Traitements : SDES, 2023
A19: * la consommation intérieure apparente de matières agrège, en tonnes, les combustibles fossiles, les produits minéraux et agricoles extraits du territoire national (métropole et DOM) ou importés sous forme de matières premières ou de produits finis, moins les exportations ; ** en volume, prix chaînés base 2014.
A20: Sources : Agreste/SSP ; douanes françaises ; Insee. Traitements : SDES, 2023
A21: En indice base 100 en 1990
A48: * la consommation intérieure apparente de matières agrège, en tonnes, les combustibles fossiles, les produits minéraux et agricoles extraits du territoire national (métropole et DOM) ou importés sous forme de matières premières ou de produits finis, moins les exportations ; ** en volume, prix chaînés base 2014.
A49: Sources : Agreste/SSP ; douanes françaises ; Insee. Traitements : SDES, 2023

Sheet Graph 4
A1: Graphique 4 : comparaison internationale de la consommation de matières par habitant en 2020
A4: Pays | B4: DMC/hab
A5: Inde | B5: 5.469
A6: Royaume-Uni | B6: 8.2
A7: Japon | B7: 10.948
A8: Espagne | B8: 9.5
A9: France | B9: 11.8
A10: UE à 19 | B10: 12.4
A11: UE à 27 | B11: 14.2
A12: Allemagne | B12: 14.2
A13: Russie | B13: 17.6
A14: États-Unis | B14: 23.8
A15: PECO* | B15: 18
A16: Chine | B16: 22.931
... A19: Chili | B19: 52.982
A20: Sources : OCDE ; SDES, 2023
A21: En tonne par habitant
C28: *PECO : Pays d’Europe centrale et orientale.
C29: Sources : OCDE ; SDES, 2023
